Workbook

Sheet Trade Tracker - Eval
A1: ZTH | B1: Date | C1: Time | D1: Asset Traded | E1: Direction | F1: Entry Price | G1: Exit Price | H1: Position Size | I1: Stop Loss | J1: Take Profit | K1: RR Targeted | L1: RR Realized | M1: Win/Loss | N1: P&L Amount | O1: P&L % | P1: Cumulative P&L | Q1: Trade Setup | R1: Notes | S1: Intrument Level | T1: Level Screenshot | U1: Trade Screenshot
A2: 7 | B2: 46251 | C2: 0.41319444 | D2: MNQ | E2: Long | F2: 30240.75 | G2: 30220 | H2: 3 | I2: 30220.75 | J2: 30280.75 | K2: =IF(AND(I2<>"",J2<>"",F2<>""), (J2-F2)/(F2-I2), "") -> 2 | L2: =IF(AND(F2<>"",G2<>"",I2<>""), (G2-F2)/(F2-I2), "") -> -1.0375 | M2: =IF(N2>0,"Win",IF(N2<0,"Loss","")) -> Loss | N2: =IF(AND(F2<>"",G2<>"",H2<>"",D2<>""), IF(E2="Long", (G2-F2)*H2*VLOOKUP(D2,Multipliers!A:B,2,FALSE), (F2-G2)*H2*VLOOKUP(D2,Multipliers!A:B,2,FALSE)), "") -> -124.5 | O2: =IF(AND(N2<>"",F2<>"",H2<>"",D2<>""), N2/(F2*H2*VLOOKUP(D2,Multipliers!A:B,2,FALSE)), "") -> -0.00068616023 | P2: =N2 -> -124.5 | Q2: BR | S2: MNQ | T2: https://www.tradingview.com/x/ygjyjXNE/ | U2: https://www.tradingview.com/x/pqKL41ZW/
A3: 8 | B3: 46251 | C3: 0.42291667 | D3: MGC | E3: Long | F3: 4461.4 | G3: 4473.4 | H3: 2 | I3: 4455.4 | J3: 4473.4 | K3: =IF(AND(I3<>"",J3<>"",F3<>""), (J3-F3)/(F3-I3), "") -> 2 | L3: =IF(AND(F3<>"",G3<>"",I3<>""), (G3-F3)/(F3-I3), "") -> 2 | M3: =IF(N3>0,"Win",IF(N3<0,"Loss","")) -> Win | N3: =IF(AND(F3<>"",G3<>"",H3<>"",D3<>""), IF(E3="Long", (G3-F3)*H3*VLOOKUP(D3,Multipliers!A:B,2,FALSE), (F3-G3)*H3*VLOOKUP(D3,Multipliers!A:B,2,FALSE)), "") -> 240 | O3: =IF(AND(N3<>"",F3<>"",H3<>"",D3<>""), N3/(F3*H3*VLOOKUP(D3,Multipliers!A:B,2,FALSE)), "") -> 0.0026897386 | P3: =P2+N3 -> 115.5 | Q3: BR | S3: MGC | T3: https://www.tradingview.com/x/soX7jXbm/ | U3: https://www.tradingview.com/x/Hz1BKRjK/
A4: 9 | B4: 46251 | C4: 0.49375 | D4: MNQ | E4: Short | F4: 30237.75 | G4: 30221.5 | H4: 3 | I4: 30257.75 | J4: 30221.5 | K4: =IF(AND(I4<>"",J4<>"",F4<>""), (J4-F4)/(F4-I4), "") -> 0.8125 | L4: =IF(AND(F4<>"",G4<>"",I4<>""), (G4-F4)/(F4-I4), "") -> 0.8125 | M4: =IF(N4>0,"Win",IF(N4<0,"Loss","")) -> Win | N4: =IF(AND(F4<>"",G4<>"",H4<>"",D4<>""), IF(E4="Long", (G4-F4)*H4*VLOOKUP(D4,Multipliers!A:B,2,FALSE), (F4-G4)*H4*VLOOKUP(D4,Multipliers!A:B,2,FALSE)), "") -> 97.5 | O4: =IF(AND(N4<>"",F4<>"",H4<>"",D4<>""), N4/(F4*H4*VLOOKUP(D4,Multipliers!A:B,2,FALSE)), "") -> 0.00053740771 | P4: =P3+N4 -> 213 | Q4: BR | S4: MNQ | U4: https://www.tradingview.com/x/pqKL41ZW/
A5: 10 | B5: 46245 | C5: 0.81082176 | D5: MGC | E5: Long | F5: 4429.1 | G5: 4430.1 | H5: 3 | I5: 4423.4 | J5: 4431.5 | K5: =IF(AND(I5<>"",J5<>"",F5<>""), (J5-F5)/(F5-I5), "") -> 0.42105263 | L5: =IF(AND(F5<>"",G5<>"",I5<>""), (G5-F5)/(F5-I5), "") -> 0.1754386 | M5: =IF(N5>0,"Win",IF(N5<0,"Loss","")) -> Win | N5: =IF(AND(F5<>"",G5<>"",H5<>"",D5<>""), IF(E5="Long", (G5-F5)*H5*VLOOKUP(D5,Multipliers!A:B,2,FALSE), (F5-G5)*H5*VLOOKUP(D5,Multipliers!A:B,2,FALSE)), "") -> 30 | O5: =IF(AND(N5<>"",F5<>"",H5<>"",D5<>""), N5/(F5*H5*VLOOKUP(D5,Multipliers!A:B,2,FALSE)), "") -> 0.0002257795 | P5: =P4+N5 -> 243 | R5: Imported from Tradovate | S5: MGC
A6: 11 | B6: 46245 | C6: 0.81194444 | D6: MGC | E6: Short | F6: 4431.6 | G6: 4430.5 | H6: 10 | J6: 4430.5 | K6: =IF(AND(I6<>"",J6<>"",F6<>""), (J6-F6)/(F6-I6), "") | L6: =IF(AND(F6<>"",G6<>"",I6<>""), (G6-F6)/(F6-I6), "") | M6: =IF(N6>0,"Win",IF(N6<0,"Loss","")) -> Win | N6: =IF(AND(F6<>"",G6<>"",H6<>"",D6<>""), IF(E6="Long", (G6-F6)*H6*VLOOKUP(D6,Multipliers!A:B,2,FALSE), (F6-G6)*H6*VLOOKUP(D6,Multipliers!A:B,2,FALSE)), "") -> 110 | O6: =IF(AND(N6<>"",F6<>"",H6<>"",D6<>""), N6/(F6*H6*VLOOKUP(D6,Multipliers!A:B,2,FALSE)), "") -> 0.00024821735 | P6: =P5+N6 -> 353 | R6: Imported from Tradovate | S6: MGC
A7: 12 | B7: 46245 | C7: 0.81283565 | D7: MGC | E7: Long | F7: 4430.6 | G7: 4426.2 | H7: 10 | I7: 4423.4 | J7: 4431.5 | K7: =IF(AND(I7<>"",J7<>"",F7<>""), (J7-F7)/(F7-I7), "") -> 0.125 | L7: =IF(AND(F7<>"",G7<>"",I7<>""), (G7-F7)/(F7-I7), "") -> -0.61111111 | M7: =IF(N7>0,"Win",IF(N7<0,"Loss","")) -> Loss | N7: =IF(AND(F7<>"",G7<>"",H7<>"",D7<>""), IF(E7="Long", (G7-F7)*H7*VLOOKUP(D7,Multipliers!A:B,2,FALSE), (F7-G7)*H7*VLOOKUP(D7,Multipliers!A:B,2,FALSE)), "") -> -440 | O7: =IF(AND(N7<>"",F7<>"",H7<>"",D7<>""), N7/(F7*H7*VLOOKUP(D7,Multipliers!A:B,2,FALSE)), "") -> -0.00099309349 | P7: =P6+N7 -> -87 | R7: Imported from Tradovate | S7: MGC
A8: 13 | B8: 46245 | C8: 0.81564815 | D8: MGC | E8: Short | F8: 4427 | G8: 4440.1 | H8: 10 | J8: 4426.8 | K8: =IF(AND(I8<>"",J8<>"",F8<>""), (J8-F8)/(F8-I8), "") | L8: =IF(AND(F8<>"",G8<>"",I8<>""), (G8-F8)/(F8-I8), "") | M8: =IF(N8>0,"Win",IF(N8<0,"Loss","")) -> Loss | N8: =IF(AND(F8<>"",G8<>"",H8<>"",D8<>""), IF(E8="Long", (G8-F8)*H8*VLOOKUP(D8,Multipliers!A:B,2,FALSE), (F8-G8)*H8*VLOOKUP(D8,Multipliers!A:B,2,FALSE)), "") -> -1310 | O8: =IF(AND(N8<>"",F8<>"",H8<>"",D8<>""), N8/(F8*H8*VLOOKUP(D8,Multipliers!A:B,2,FALSE)), "") -> -0.0029591145 | P8: =P7+N8 -> -1397 | R8: Imported from Tradovate | S8: MGC
A9: 14 | B9: 46245 | C9: 0.85517361 | D9: MGC | E9: Long | F9: 4440.1 | G9: 4443.8 | H9: 10 | J9: 4443.8 | K9: =IF(AND(I9<>"",J9<>"",F9<>""), (J9-F9)/(F9-I9), "") | L9: =IF(AND(F9<>"",G9<>"",I9<>""), (G9-F9)/(F9-I9), "") | M9: =IF(N9>0,"Win",IF(N9<0,"Loss","")) -> Win | N9: =IF(AND(F9<>"",G9<>"",H9<>"",D9<>""), IF(E9="Long", (G9-F9)*H9*VLOOKUP(D9,Multipliers!A:B,2,FALSE), (F9-G9)*H9*VLOOKUP(D9,Multipliers!A:B,2,FALSE)), "") -> 370 | O9: =IF(AND(N9<>"",F9<>"",H9<>"",D9<>""), N9/(F9*H9*VLOOKUP(D9,Multipliers!A:B,2,FALSE)), "") -> 0.00083331456 | P9: =P8+N9 -> -1027 | R9: Imported from Tradovate | S9: MGC
A10: 15 | B10: 46245 | C10: 0.88615741 | D10: MGC | E10: Long | F10: 4457.1667 | G10: 4457.8 | H10: 30 | J10: 4472.1 | K10: =IF(AND(I10<>"",J10<>"",F10<>""), (J10-F10)/(F10-I10), "") | L10: =IF(AND(F10<>"",G10<>"",I10<>""), (G10-F10)/(F10-I10), "") | M10: =IF(N10>0,"Win",IF(N10<0,"Loss","")) -> Win | N10: =IF(AND(F10<>"",G10<>"",H10<>"",D10<>""), IF(E10="Long", (G10-F10)*H10*VLOOKUP(D10,Multipliers!A:B,2,FALSE), (F10-G10)*H10*VLOOKUP(D10,Multipliers!A:B,2,FALSE)), "") -> 189.9999 | O10: =IF(AND(N10<>"",F10<>"",H10<>"",D10<>""), N10/(F10*H10*VLOOKUP(D10,Multipliers!A:B,2,FALSE)), "") -> 0.00014209318 | P10: =P9+N10 -> -837.0001 | R10: Imported from Tradovate | S10: MGC
A11: 16 | B11: 46245 | C11: 0.9446412 | D11: MGC | E11: Long | F11: 4461.8 | G11: 4469 | H11: 30 | J11: 4474.1 | K11: =IF(AND(I11<>"",J11<>"",F11<>""), (J11-F11)/(F11-I11), "") | L11: =IF(AND(F11<>"",G11<>"",I11<>""), (G11-F11)/(F11-I11), "") | M11: =IF(N11>0,"Win",IF(N11<0,"Loss","")) -> Win | N11: =IF(AND(F11<>"",G11<>"",H11<>"",D11<>""), IF(E11="Long", (G11-F11)*H11*VLOOKUP(D11,Multipliers!A:B,2,FALSE), (F11-G11)*H11*VLOOKUP(D11,Multipliers!A:B,2,FALSE)), "") -> 2160 | O11: =IF(AND(N11<>"",F11<>"",H11<>"",D11<>""), N11/(F11*H11*VLOOKUP(D11,Multipliers!A:B,2,FALSE)), "") -> 0.0016136985 | P11: =P10+N11 -> 1322.9999 | R11: Imported from Tradovate | S11: MGC
A12: 17 | B12: 46245 | C12: 0.95865741 | D12: MGC | E12: Long | F12: 4472.3 | G12: 4470.9 | H12: 20 | J12: 4475.9 | K12: =IF(AND(I12<>"",J12<>"",F12<>""), (J12-F12)/(F12-I12), "") | L12: =IF(AND(F12<>"",G12<>"",I12<>""), (G12-F12)/(F12-I12), "") | M12: =IF(N12>0,"Win",IF(N12<0,"Loss","")) -> Loss | N12: =IF(AND(F12<>"",G12<>"",H12<>"",D12<>""), IF(E12="Long", (G12-F12)*H12*VLOOKUP(D12,Multipliers!A:B,2,FALSE), (F12-G12)*H12*VLOOKUP(D12,Multipliers!A:B,2,FALSE)), "") -> -280 | O12: =IF(AND(N12<>"",F12<>"",H12<>"",D12<>""), N12/(F12*H12*VLOOKUP(D12,Multipliers!A:B,2,FALSE)), "") -> -0.00031303803 | P12: =P11+N12 -> 1042.9999 | R12: Imported from Tradovate | S12: MGC
A13: 18 | B13: 46245 | C13: 0.96665509 | D13: MGC | E13: Long | F13: 4473.9 | G13: 4464.8 | H13: 10 | K13: =IF(AND(I13<>"",J13<>"",F13<>""), (J13-F13)/(F13-I13), "") | L13: =IF(AND(F13<>"",G13<>"",I13<>""), (G13-F13)/(F13-I13), "") | M13: =IF(N13>0,"Win",IF(N13<0,"Loss","")) -> Loss | N13: =IF(AND(F13<>"",G13<>"",H13<>"",D13<>""), IF(E13="Long", (G13-F13)*H13*VLOOKUP(D13,Multipliers!A:B,2,FALSE), (F13-G13)*H13*VLOOKUP(D13,Multipliers!A:B,2,FALSE)), "") -> -910 | O13: =IF(AND(N13<>"",F13<>"",H13<>"",D13<>""), N13/(F13*H13*VLOOKUP(D13,Multipliers!A:B,2,FALSE)), "") -> -0.0020340195 | P13: =P12+N13 -> 132.9999 | R13: Imported from Tradovate | S13: MGC
A14: 19 | B14: 46245 | C14: 0.97626157 | D14: MGC | E14: Long | F14: 4467.3 | G14: 4465.9 | H14: 10 | K14: =IF(AND(I14<>"",J14<>"",F14<>""), (J14-F14)/(F14-I14), "") | L14: =IF(AND(F14<>"",G14<>"",I14<>""), (G14-F14)/(F14-I14), "") | M14: =IF(N14>0,"Win",IF(N14<0,"Loss","")) -> Loss | N14: =IF(AND(F14<>"",G14<>"",H14<>"",D14<>""), IF(E14="Long", (G14-F14)*H14*VLOOKUP(D14,Multipliers!A:B,2,FALSE), (F14-G14)*H14*VLOOKUP(D14,Multipliers!A:B,2,FALSE)), "") -> -140 | O14: =IF(AND(N14<>"",F14<>"",H14<>"",D14<>""), N14/(F14*H14*VLOOKUP(D14,Multipliers!A:B,2,FALSE)), "") -> -0.0003133884 | P14: =P13+N14 -> -7.0001 | R14: Imported from Tradovate | S14: MGC
A15: 20 | B15: 46245 | C15: 0.9837037 | D15: MGC | E15: Short | F15: 4461.05 | G15: 4458.6 | H15: 20 | J15: 4458.6 | K15: =IF(AND(I15<>"",J15<>"",F15<>""), (J15-F15)/(F15-I15), "") | L15: =IF(AND(F15<>"",G15<>"",I15<>""), (G15-F15)/(F15-I15), "") | M15: =IF(N15>0,"Win",IF(N15<0,"Loss","")) -> Win | N15: =IF(AND(F15<>"",G15<>"",H15<>"",D15<>""), IF(E15="Long", (G15-F15)*H15*VLOOKUP(D15,Multipliers!A:B,2,FALSE), (F15-G15)*H15*VLOOKUP(D15,Multipliers!A:B,2,FALSE)), "") -> 490 | O15: =IF(AND(N15<>"",F15<>"",H15<>"",D15<>""), N15/(F15*H15*VLOOKUP(D15,Multipliers!A:B,2,FALSE)), "") -> 0.00054919806 | P15: =P14+N15 -> 482.9999 | R15: Imported from Tradovate | S15: MGC
A16: 21 | B16: 46246 | C16: 0.38358796 | D16: MNQ | E16: Long | F16: 29931.25 | G16: 29936 | H16: 5 | J16: 29936 | K16: =IF(AND(I16<>"",J16<>"",F16<>""), (J16-F16)/(F16-I16), "") | L16: =IF(AND(F16<>"",G16<>"",I16<>""), (G16-F16)/(F16-I16), "") | M16: =IF(N16>0,"Win",IF(N16<0,"Loss","")) -> Win | N16: =IF(AND(F16<>"",G16<>"",H16<>"",D16<>""), IF(E16="Long", (G16-F16)*H16*VLOOKUP(D16,Multipliers!A:B,2,FALSE), (F16-G16)*H16*VLOOKUP(D16,Multipliers!A:B,2,FALSE)), "") -> 47.5 | O16: =IF(AND(N16<>"",F16<>"",H16<>"",D16<>""), N16/(F16*H16*VLOOKUP(D16,Multipliers!A:B,2,FALSE)), "") -> 0.00015869701 | P16: =P15+N16 -> 530.4999 | R16: Imported from Tradovate | S16: MNQ
A17: 22 | B17: 46246 | C17: 0.39325231 | D17: MGC | E17: Short | F17: 4475.7 | G17: 4474 | H17: 10 | J17: 4474 | K17: =IF(AND(I17<>"",J17<>"",F17<>""), (J17-F17)/(F17-I17), "") | L17: =IF(AND(F17<>"",G17<>"",I17<>""), (G17-F17)/(F17-I17), "") | M17: =IF(N17>0,"Win",IF(N17<0,"Loss","")) -> Win | N17: =IF(AND(F17<>"",G17<>"",H17<>"",D17<>""), IF(E17="Long", (G17-F17)*H17*VLOOKUP(D17,Multipliers!A:B,2,FALSE), (F17-G17)*H17*VLOOKUP(D17,Multipliers!A:B,2,FALSE)), "") -> 170 | O17: =IF(AND(N17<>"",F17<>"",H17<>"",D17<>""), N17/(F17*H17*VLOOKUP(D17,Multipliers!A:B,2,FALSE)), "") -> 0.00037982885 | P17: =P16+N17 -> 700.4999 | R17: Imported from Tradovate | S17: MGC
A18: 23 | B18: 46246 | C18: 0.40153935 | D18: MNQ | E18: Short | F18: 29915.75 | G18: 29881 | H18: 1 | J18: 29881 | K18: =IF(AND(I18<>"",J18<>"",F18<>""), (J18-F18)/(F18-I18), "") | L18: =IF(AND(F18<>"",G18<>"",I18<>""), (G18-F18)/(F18-I18), "") | M18: =IF(N18>0,"Win",IF(N18<0,"Loss","")) -> Win | N18: =IF(AND(F18<>"",G18<>"",H18<>"",D18<>""), IF(E18="Long", (G18-F18)*H18*VLOOKUP(D18,Multipliers!A:B,2,FALSE), (F18-G18)*H18*VLOOKUP(D18,Multipliers!A:B,2,FALSE)), "") -> 69.5 | O18: =IF(AND(N18<>"",F18<>"",H18<>"",D18<>""), N18/(F18*H18*VLOOKUP(D18,Multipliers!A:B,2,FALSE)), "") -> 0.0011615955 | P18: =P17+N18 -> 769.9999 | R18: Imported from Tradovate | S18: MNQ
A19: 24 | B19: 46246 | C19: 0.4109838 | D19: MGC | E19: Long | F19: 4490 | G19: 4485.4 | H19: 10 | K19: =IF(AND(I19<>"",J19<>"",F19<>""), (J19-F19)/(F19-I19), "") | L19: =IF(AND(F19<>"",G19<>"",I19<>""), (G19-F19)/(F19-I19), "") | M19: =IF(N19>0,"Win",IF(N19<0,"Loss","")) -> Loss | N19: =IF(AND(F19<>"",G19<>"",H19<>"",D19<>""), IF(E19="Long", (G19-F19)*H19*VLOOKUP(D19,Multipliers!A:B,2,FALSE), (F19-G19)*H19*VLOOKUP(D19,Multipliers!A:B,2,FALSE)), "") -> -460 | O19: =IF(AND(N19<>"",F19<>"",H19<>"",D19<>""), N19/(F19*H19*VLOOKUP(D19,Multipliers!A:B,2,FALSE)), "") -> -0.0010244989 | P19: =P18+N19 -> 309.9999 | R19: Imported from Tradovate | S19: MGC
A20: 25 | B20: 46246 | C20: 0.45519676 | D20: MNQ | E20: Long | F20: 29863 | G20: 29878.5 | H20: 3 | I20: 29833 | J20: 29878.5 | K20: =IF(AND(I20<>"",J20<>"",F20<>""), (J20-F20)/(F20-I20), "") -> 0.51666667 | L20: =IF(AND(F20<>"",G20<>"",I20<>""), (G20-F20)/(F20-I20), "") -> 0.51666667 | M20: =IF(N20>0,"Win",IF(N20<0,"Loss","")) -> Win | N20: =IF(AND(F20<>"",G20<>"",H20<>"",D20<>""), IF(E20="Long", (G20-F20)*H20*VLOOKUP(D20,Multipliers!A:B,2,FALSE), (F20-G20)*H20*VLOOKUP(D20,Multipliers!A:B,2,FALSE)), "") -> 93 | O20: =IF(AND(N20<>"",F20<>"",H20<>"",D20<>""), N20/(F20*H20*VLOOKUP(D20,Multipliers!A:B,2,FALSE)), "") -> 0.00051903694 | P20: =P19+N20 -> 402.9999 | R20: Imported from Tradovate | S20: MNQ
A21: 26 | B21: 46246 | C21: 0.47391204 | D21: MNQ | E21: Long | F21: 29854 | G21: 29879.75 | H21: 3 | I21: 29834.5 | J21: 29894.5 | K21: =IF(AND(I21<>"",J21<>"",F21<>""), (J21-F21)/(F21-I21), "") -> 2.0769231 | L21: =IF(AND(F21<>"",G21<>"",I21<>""), (G21-F21)/(F21-I21), "") -> 1.3205128 | M21: =IF(N21>0,"Win",IF(N21<0,"Loss","")) -> Win | N21: =IF(AND(F21<>"",G21<>"",H21<>"",D21<>""), IF(E21="Long", (G21-F21)*H21*VLOOKUP(D21,Multipliers!A:B,2,FALSE), (F21-G21)*H21*VLOOKUP(D21,Multipliers!A:B,2,FALSE)), "") -> 154.5 | O21: =IF(AND(N21<>"",F21<>"",H21<>"",D21<>""), N21/(F21*H21*VLOOKUP(D21,Multipliers!A:B,2,FALSE)), "") -> 0.00086253098 | P21: =P20+N21 -> 557.4999 | R21: Imported from Tradovate | S21: MNQ
A22: 27 | B22: 46246 | C22: 0.480625 | D22: MNQ | E22: Long | F22: 29855.75 | G22: 29833 | H22: 3 | I22: 29834.5 | J22: 29894.5 | K22: =IF(AND(I22<>"",J22<>"",F22<>""), (J22-F22)/(F22-I22), "") -> 1.8235294 | L22: =IF(AND(F22<>"",G22<>"",I22<>""), (G22-F22)/(F22-I22), "") -> -1.0705882 | M22: =IF(N22>0,"Win",IF(N22<0,"Loss","")) -> Loss | N22: =IF(AND(F22<>"",G22<>"",H22<>"",D22<>""), IF(E22="Long", (G22-F22)*H22*VLOOKUP(D22,Multipliers!A:B,2,FALSE), (F22-G22)*H22*VLOOKUP(D22,Multipliers!A:B,2,FALSE)), "") -> -136.5 | O22: =IF(AND(N22<>"",F22<>"",H22<>"",D22<>""), N22/(F22*H22*VLOOKUP(D22,Multipliers!A:B,2,FALSE)), "") -> -0.00076199727 | P22: =P21+N22 -> 420.9999 | R22: Imported from Tradovate | S22: MNQ
A23: 28 | B23: 46246 | C23: 0.49825231 | D23: MNQ | E23: Short | F23: 29838.25 | G23: 29862.25 | H23: 3 | I23: 29858.5 | J23: 29823.5 | K23: =IF(AND(I23<>"",J23<>"",F23<>""), (J23-F23)/(F23-I23), "") -> 0.72839506 | L23: =IF(AND(F23<>"",G23<>"",I23<>""), (G23-F23)/(F23-I23), "") -> -1.1851852 | M23: =IF(N23>0,"Win",IF(N23<0,"Loss","")) -> Loss | N23: =IF(AND(F23<>"",G23<>"",H23<>"",D23<>""), IF(E23="Long", (G23-F23)*H23*VLOOKUP(D23,Multipliers!A:B,2,FALSE), (F23-G23)*H23*VLOOKUP(D23,Multipliers!A:B,2,FALSE)), "") -> -144 | O23: =IF(AND(N23<>"",F23<>"",H23<>"",D23<>""), N23/(F23*H23*VLOOKUP(D23,Multipliers!A:B,2,FALSE)), "") -> -0.00080433672 | P23: =P22+N23 -> 276.9999 | R23: Imported from Tradovate | S23: MNQ
A24: 29 | B24: 46246 | C24: 0.59178241 | D24: MGC | E24: Short | F24: 4465.4 | G24: 4471.9 | H24: 3 | I24: 4471.8 | J24: 4458.5 | K24: =IF(AND(I24<>"",J24<>"",F24<>""), (J24-F24)/(F24-I24), "") -> 1.078125 | L24: =IF(AND(F24<>"",G24<>"",I24<>""), (G24-F24)/(F24-I24), "") -> -1.015625 | M24: =IF(N24>0,"Win",IF(N24<0,"Loss","")) -> Loss | N24: =IF(AND(F24<>"",G24<>"",H24<>"",D24<>""), IF(E24="Long", (G24-F24)*H24*VLOOKUP(D24,Multipliers!A:B,2,FALSE), (F24-G24)*H24*VLOOKUP(D24,Multipliers!A:B,2,FALSE)), "") -> -195 | O24: =IF(AND(N24<>"",F24<>"",H24<>"",D24<>""), N24/(F24*H24*VLOOKUP(D24,Multipliers!A:B,2,FALSE)), "") -> -0.0014556367 | P24: =P23+N24 -> 81.9999 | R24: Imported from Tradovate | S24: MGC
A25: 30 | B25: 46247 | C25: 0.36866898 | D25: MGC | E25: Long | F25: 4450.95 | G25: 4448.1 | H25: 2 | I25: 4444.4 | J25: 4451.8 | K25: =IF(AND(I25<>"",J25<>"",F25<>""), (J25-F25)/(F25-I25), "") -> 0.12977099 | L25: =IF(AND(F25<>"",G25<>"",I25<>""), (G25-F25)/(F25-I25), "") -> -0.4351145 | M25: =IF(N25>0,"Win",IF(N25<0,"Loss","")) -> Loss | N25: =IF(AND(F25<>"",G25<>"",H25<>"",D25<>""), IF(E25="Long", (G25-F25)*H25*VLOOKUP(D25,Multipliers!A:B,2,FALSE), (F25-G25)*H25*VLOOKUP(D25,Multipliers!A:B,2,FALSE)), "") -> -57 | O25: =IF(AND(N25<>"",F25<>"",H25<>"",D25<>""), N25/(F25*H25*VLOOKUP(D25,Multipliers!A:B,2,FALSE)), "") -> -0.00064031274 | P25: =P24+N25 -> 24.9999 | R25: Imported from Tradovate | S25: MGC
A26: 31 | B26: 46247 | C26: 0.40733796 | D26: MNQ | E26: Long | F26: 30089.5 | G26: 30127 | H26: 5 | I26: 30067 | J26: 30127 | K26: =IF(AND(I26<>"",J26<>"",F26<>""), (J26-F26)/(F26-I26), "") -> 1.6666667 | L26: =IF(AND(F26<>"",G26<>"",I26<>""), (G26-F26)/(F26-I26), "") -> 1.6666667 | M26: =IF(N26>0,"Win",IF(N26<0,"Loss","")) -> Win | N26: =IF(AND(F26<>"",G26<>"",H26<>"",D26<>""), IF(E26="Long", (G26-F26)*H26*VLOOKUP(D26,Multipliers!A:B,2,FALSE), (F26-G26)*H26*VLOOKUP(D26,Multipliers!A:B,2,FALSE)), "") -> 375 | O26: =IF(AND(N26<>"",F26<>"",H26<>"",D26<>""), N26/(F26*H26*VLOOKUP(D26,Multipliers!A:B,2,FALSE)), "") -> 0.0012462819 | P26: =P25+N26 -> 399.9999 | R26: Imported from Tradovate | S26: MNQ
A27: 32 | B27: 46247 | C27: 0.47510417 | D27: MGC | E27: Short | F27: 4427.5 | G27: 4418 | H27: 3 | J27: 4418 | K27: =IF(AND(I27<>"",J27<>"",F27<>""), (J27-F27)/(F27-I27), "") | L27: =IF(AND(F27<>"",G27<>"",I27<>""), (G27-F27)/(F27-I27), "") | M27: =IF(N27>0,"Win",IF(N27<0,"Loss","")) -> Win | N27: =IF(AND(F27<>"",G27<>"",H27<>"",D27<>""), IF(E27="Long", (G27-F27)*H27*VLOOKUP(D27,Multipliers!A:B,2,FALSE), (F27-G27)*H27*VLOOKUP(D27,Multipliers!A:B,2,FALSE)), "") -> 285 | O27: =IF(AND(N27<>"",F27<>"",H27<>"",D27<>""), N27/(F27*H27*VLOOKUP(D27,Multipliers!A:B,2,FALSE)), "") -> 0.0021456804 | P27: =P26+N27 -> 684.9999 | R27: Imported from Tradovate | S27: MGC
A28: 33 | B28: 46247 | C28: 0.95162037 | D28: MGC | E28: Long | F28: 4371.8 | G28: 4369.6 | H28: 3 | K28: =IF(AND(I28<>"",J28<>"",F28<>""), (J28-F28)/(F28-I28), "") | L28: =IF(AND(F28<>"",G28<>"",I28<>""), (G28-F28)/(F28-I28), "") | M28: =IF(N28>0,"Win",IF(N28<0,"Loss","")) -> Loss | N28: =IF(AND(F28<>"",G28<>"",H28<>"",D28<>""), IF(E28="Long", (G28-F28)*H28*VLOOKUP(D28,Multipliers!A:B,2,FALSE), (F28-G28)*H28*VLOOKUP(D28,Multipliers!A:B,2,FALSE)), "") -> -66 | O28: =IF(AND(N28<>"",F28<>"",H28<>"",D28<>""), N28/(F28*H28*VLOOKUP(D28,Multipliers!A:B,2,FALSE)), "") -> -0.00050322522 | P28: =P27+N28 -> 618.9999 | R28: Imported from Tradovate | S28: MGC
A29: 34 | B29: 46247 | C29: 0.95800926 | D29: MGC | E29: Short | F29: 4370.5 | G29: 4377 | H29: 3 | I29: 4377 | J29: 4369.3 | K29: =IF(AND(I29<>"",J29<>"",F29<>""), (J29-F29)/(F29-I29), "") -> 0.18461538 | L29: =IF(AND(F29<>"",G29<>"",I29<>""), (G29-F29)/(F29-I29), "") -> -1 | M29: =IF(N29>0,"Win",IF(N29<0,"Loss","")) -> Loss | N29: =IF(AND(F29<>"",G29<>"",H29<>"",D29<>""), IF(E29="Long", (G29-F29)*H29*VLOOKUP(D29,Multipliers!A:B,2,FALSE), (F29-G29)*H29*VLOOKUP(D29,Multipliers!A:B,2,FALSE)), "") -> -195 | O29: =IF(AND(N29<>"",F29<>"",H29<>"",D29<>""), N29/(F29*H29*VLOOKUP(D29,Multipliers!A:B,2,FALSE)), "") -> -0.001487244 | P29: =P28+N29 -> 423.9999 | R29: Imported from Tradovate | S29: MGC
A30: 35 | B30: 46248 | C30: 0.40767361 | D30: MNQ | E30: Long | F30: 30233 | G30: 30255.75 | H30: 3 | J30: 30272 | K30: =IF(AND(I30<>"",J30<>"",F30<>""), (J30-F30)/(F30-I30), "") | L30: =IF(AND(F30<>"",G30<>"",I30<>""), (G30-F30)/(F30-I30), "") | M30: =IF(N30>0,"Win",IF(N30<0,"Loss","")) -> Win | N30: =IF(AND(F30<>"",G30<>"",H30<>"",D30<>""), IF(E30="Long", (G30-F30)*H30*VLOOKUP(D30,Multipliers!A:B,2,FALSE), (F30-G30)*H30*VLOOKUP(D30,Multipliers!A:B,2,FALSE)), "") -> 136.5 | O30: =IF(AND(N30<>"",F30<>"",H30<>"",D30<>""), N30/(F30*H30*VLOOKUP(D30,Multipliers!A:B,2,FALSE)), "") -> 0.000752489 | P30: =P29+N30 -> 560.4999 | R30: Imported from Tradovate | S30: MNQ
A31: 36 | B31: 46248 | C31: 0.41525463 | D31: MNQ | E31: Long | F31: 30221 | G31: 30225.5 | H31: 3 | I31: 30201 | J31: 30225.5 | K31: =IF(AND(I31<>"",J31<>"",F31<>""), (J31-F31)/(F31-I31), "") -> 0.225 | L31: =IF(AND(F31<>"",G31<>"",I31<>""), (G31-F31)/(F31-I31), "") -> 0.225 | M31: =IF(N31>0,"Win",IF(N31<0,"Loss","")) -> Win | N31: =IF(AND(F31<>"",G31<>"",H31<>"",D31<>""), IF(E31="Long", (G31-F31)*H31*VLOOKUP(D31,Multipliers!A:B,2,FALSE), (F31-G31)*H31*VLOOKUP(D31,Multipliers!A:B,2,FALSE)), "") -> 27 | O31: =IF(AND(N31<>"",F31<>"",H31<>"",D31<>""), N31/(F31*H31*VLOOKUP(D31,Multipliers!A:B,2,FALSE)), "") -> 0.00014890308 | P31: =P30+N31 -> 587.4999 | R31: Imported from Tradovate | S31: MNQ
A32: 37 | B32: 46248 | C32: 0.49888889 | D32: MNQ | E32: Short | F32: 30072.5 | G32: 30099.5 | H32: 3 | I32: 30099.5 | J32: 30058.25 | K32: =IF(AND(I32<>"",J32<>"",F32<>""), (J32-F32)/(F32-I32), "") -> 0.52777778 | L32: =IF(AND(F32<>"",G32<>"",I32<>""), (G32-F32)/(F32-I32), "") -> -1 | M32: =IF(N32>0,"Win",IF(N32<0,"Loss","")) -> Loss | N32: =IF(AND(F32<>"",G32<>"",H32<>"",D32<>""), IF(E32="Long", (G32-F32)*H32*VLOOKUP(D32,Multipliers!A:B,2,FALSE), (F32-G32)*H32*VLOOKUP(D32,Multipliers!A:B,2,FALSE)), "") -> -162 | O32: =IF(AND(N32<>"",F32<>"",H32<>"",D32<>""), N32/(F32*H32*VLOOKUP(D32,Multipliers!A:B,2,FALSE)), "") -> -0.00089783024 | P32: =P31+N32 -> 425.4999 | R32: Imported from Tradovate | S32: MNQ
A33: 38 | B33: 46248 | C33: 0.5287037 | D33: MNQ | E33: Short | F33: 30068.5 | G33: 30064 | H33: 3 | I33: 30088.5 | J33: 30064 | K33: =IF(AND(I33<>"",J33<>"",F33<>""), (J33-F33)/(F33-I33), "") -> 0.225 | L33: =IF(AND(F33<>"",G33<>"",I33<>""), (G33-F33)/(F33-I33), "") -> 0.225 | M33: =IF(N33>0,"Win",IF(N33<0,"Loss","")) -> Win | N33: =IF(AND(F33<>"",G33<>"",H33<>"",D33<>""), IF(E33="Long", (G33-F33)*H33*VLOOKUP(D33,Multipliers!A:B,2,FALSE), (F33-G33)*H33*VLOOKUP(D33,Multipliers!A:B,2,FALSE)), "") -> 27 | O33: =IF(AND(N33<>"",F33<>"",H33<>"",D33<>""), N33/(F33*H33*VLOOKUP(D33,Multipliers!A:B,2,FALSE)), "") -> 0.00014965828 | P33: =P32+N33 -> 452.4999 | R33: Imported from Tradovate | S33: MNQ
A34: 39 | B34: 46248 | C34: 0.53212963 | D34: MNQ | E34: Long | F34: 30067 | G34: 30071.25 | H34: 5 | I34: 30047.75 | J34: 30074.5 | K34: =IF(AND(I34<>"",J34<>"",F34<>""), (J34-F34)/(F34-I34), "") -> 0.38961039 | L34: =IF(AND(F34<>"",G34<>"",I34<>""), (G34-F34)/(F34-I34), "") -> 0.22077922 | M34: =IF(N34>0,"Win",IF(N34<0,"Loss","")) -> Win | N34: =IF(AND(F34<>"",G34<>"",H34<>"",D34<>""), IF(E34="Long", (G34-F34)*H34*VLOOKUP(D34,Multipliers!A:B,2,FALSE), (F34-G34)*H34*VLOOKUP(D34,Multipliers!A:B,2,FALSE)), "") -> 42.5 | O34: =IF(AND(N34<>"",F34<>"",H34<>"",D34<>""), N34/(F34*H34*VLOOKUP(D34,Multipliers!A:B,2,FALSE)), "") -> 0.00014135098 | P34: =P33+N34 -> 494.9999 | R34: Imported from Tradovate | S34: MNQ
A35: 40 | B35: 46248 | C35: 0.53502315 | D35: MNQ | E35: Long | F35: 30064.5 | G35: 30068 | H35: 5 | J35: 30074.5 | K35: =IF(AND(I35<>"",J35<>"",F35<>""), (J35-F35)/(F35-I35), "") | L35: =IF(AND(F35<>"",G35<>"",I35<>""), (G35-F35)/(F35-I35), "") | M35: =IF(N35>0,"Win",IF(N35<0,"Loss","")) -> Win | N35: =IF(AND(F35<>"",G35<>"",H35<>"",D35<>""), IF(E35="Long", (G35-F35)*H35*VLOOKUP(D35,Multipliers!A:B,2,FALSE), (F35-G35)*H35*VLOOKUP(D35,Multipliers!A:B,2,FALSE)), "") -> 35 | O35: =IF(AND(N35<>"",F35<>"",H35<>"",D35<>""), N35/(F35*H35*VLOOKUP(D35,Multipliers!A:B,2,FALSE)), "") -> 0.00011641637 | P35: =P34+N35 -> 529.9999 | R35: Imported from Tradovate | S35: MNQ
A36: 41 | B36: 46252 | C36: 0.41706019 | D36: MGC | E36: Short | F36: 4454.7 | G36: 4460 | H36: 3 | I36: 4459.9 | J36: 4454 | K36: =IF(AND(I36<>"",J36<>"",F36<>""), (J36-F36)/(F36-I36), "") -> 0.13461538 | L36: =IF(AND(F36<>"",G36<>"",I36<>""), (G36-F36)/(F36-I36), "") -> -1.0192308 | M36: =IF(N36>0,"Win",IF(N36<0,"Loss","")) -> Loss | N36: =IF(AND(F36<>"",G36<>"",H36<>"",D36<>""), IF(E36="Long", (G36-F36)*H36*VLOOKUP(D36,Multipliers!A:B,2,FALSE), (F36-G36)*H36*VLOOKUP(D36,Multipliers!A:B,2,FALSE)), "") -> -159 | O36: =IF(AND(N36<>"",F36<>"",H36<>"",D36<>""), N36/(F36*H36*VLOOKUP(D36,Multipliers!A:B,2,FALSE)), "") -> -0.0011897546 | P36: =P35+N36 -> 370.9999 | R36: Imported from Tradovate | S36: MGC
A37: 42 | B37: 46252 | C37: 0.42253472 | D37: MGC | E37: Long | F37: 4454.2 | G37: 4448.2 | H37: 3 | I37: 4448.2 | J37: 4467 | K37: =IF(AND(I37<>"",J37<>"",F37<>""), (J37-F37)/(F37-I37), "") -> 2.1333333 | L37: =IF(AND(F37<>"",G37<>"",I37<>""), (G37-F37)/(F37-I37), "") -> -1 | M37: =IF(N37>0,"Win",IF(N37<0,"Loss","")) -> Loss | N37: =IF(AND(F37<>"",G37<>"",H37<>"",D37<>""), IF(E37="Long", (G37-F37)*H37*VLOOKUP(D37,Multipliers!A:B,2,FALSE), (F37-G37)*H37*VLOOKUP(D37,Multipliers!A:B,2,FALSE)), "") -> -180 | O37: =IF(AND(N37<>"",F37<>"",H37<>"",D37<>""), N37/(F37*H37*VLOOKUP(D37,Multipliers!A:B,2,FALSE)), "") -> -0.0013470432 | P37: =P36+N37 -> 190.9999 | R37: Imported from Tradovate | S37: MGC
A38: 43 | B38: 46252 | C38: 0.42832176 | D38: MNQ | E38: Short | F38: 29614 | G38: 29634 | H38: 2 | I38: 29634 | J38: 29574 | K38: =IF(AND(I38<>"",J38<>"",F38<>""), (J38-F38)/(F38-I38), "") -> 2 | L38: =IF(AND(F38<>"",G38<>"",I38<>""), (G38-F38)/(F38-I38), "") -> -1 | M38: =IF(N38>0,"Win",IF(N38<0,"Loss","")) -> Loss | N38: =IF(AND(F38<>"",G38<>"",H38<>"",D38<>""), IF(E38="Long", (G38-F38)*H38*VLOOKUP(D38,Multipliers!A:B,2,FALSE), (F38-G38)*H38*VLOOKUP(D38,Multipliers!A:B,2,FALSE)), "") -> -80 | O38: =IF(AND(N38<>"",F38<>"",H38<>"",D38<>""), N38/(F38*H38*VLOOKUP(D38,Multipliers!A:B,2,FALSE)), "") -> -0.00067535625 | P38: =P37+N38 -> 110.9999 | R38: Imported from Tradovate | S38: MNQ
A39: 44 | B39: 46252 | C39: 0.43178241 | D39: MNQ | E39: Short | F39: 29607.5 | G39: 29656.75 | H39: 3 | I39: 29649 | J39: 29552 | K39: =IF(AND(I39<>"",J39<>"",F39<>""), (J39-F39)/(F39-I39), "") -> 1.3373494 | L39: =IF(AND(F39<>"",G39<>"",I39<>""), (G39-F39)/(F39-I39), "") -> -1.186747 | M39: =IF(N39>0,"Win",IF(N39<0,"Loss","")) -> Loss | N39: =IF(AND(F39<>"",G39<>"",H39<>"",D39<>""), IF(E39="Long", (G39-F39)*H39*VLOOKUP(D39,Multipliers!A:B,2,FALSE), (F39-G39)*H39*VLOOKUP(D39,Multipliers!A:B,2,FALSE)), "") -> -295.5 | O39: =IF(AND(N39<>"",F39<>"",H39<>"",D39<>""), N39/(F39*H39*VLOOKUP(D39,Multipliers!A:B,2,FALSE)), "") -> -0.0016634299 | P39: =P38+N39 -> -184.5001 | R39: Imported from Tradovate | S39: MNQ
A40: 45 | B40: 46252 | C40: 0.45059028 | D40: MGC | E40: Short | F40: 4444.2 | G40: 4434.5 | H40: 2 | I40: 4447.8 | J40: 4434.5 | K40: =IF(AND(I40<>"",J40<>"",F40<>""), (J40-F40)/(F40-I40), "") -> 2.6944444 | L40: =IF(AND(F40<>"",G40<>"",I40<>""), (G40-F40)/(F40-I40), "") -> 2.6944444 | M40: =IF(N40>0,"Win",IF(N40<0,"Loss","")) -> Win | N40: =IF(AND(F40<>"",G40<>"",H40<>"",D40<>""), IF(E40="Long", (G40-F40)*H40*VLOOKUP(D40,Multipliers!A:B,2,FALSE), (F40-G40)*H40*VLOOKUP(D40,Multipliers!A:B,2,FALSE)), "") -> 194 | O40: =IF(AND(N40<>"",F40<>"",H40<>"",D40<>""), N40/(F40*H40*VLOOKUP(D40,Multipliers!A:B,2,FALSE)), "") -> 0.00218262 | P40: =P39+N40 -> 9.4999 | R40: Imported from Tradovate | S40: MGC
...

Sheet Multipliers
A1: Asset | B1: Multiplier
A2: ES | B2: 50
A3: MES | B3: 5
A4: NQ | B4: 20
A5: MNQ | B5: 2
A6: YM | B6: 5
A7: RTY | B7: 50
A8: GC | B8: 100
A9: MGC | B9: 10
A10: CL | B10: 1000
A11: MCL | B11: 100
A12: QM | B12: 500
A13: MYM | B13: 0.5
A14: M2K | B14: 5

Sheet Analysis
A1: Overview
A2: Generated | B2: 2026-08-23 23:38
A3: Date range | B3: 2026-08-11 → 2026-08-23
A4: Trades | B4: 51
A5: Win rate | B5: 52.9%
A6: Total P&L | B6: 1492.5
A7: Profit factor | B7: 1.25
A8: Expectancy / trade | B8: 29.26
A9: Avg win | B9: 272.78
A10: Avg loss | B10: -244.69
A11: Avg RR targeted | B11: 1.45
A12: Avg RR realized | B12: 0
A13: Max drawdown | B13: -1750
A14: Max win streak | B14: 4
A15: Max loss streak | B15: 4
A17: By Setup
A18: Setup | B18: Trades | C18: Win % | D18: Total P&L | E18: Expectancy
A19: (blank) | B19: 48 | C19: 52% | D19: 1279.5 | E19: 26.66
A20: BR | B20: 3 | C20: 67% | D20: 213 | E20: 71
A22: By Instrument
A23: Instrument | B23: Trades | C23: Win % | D23: Total P&L | E23: Expectancy
A24: MGC | B24: 30 | C24: 47% | D24: 1001 | E24: 33.37
A25: MNQ | B25: 21 | C25: 62% | D25: 491.5 | E25: 23.4
A27: By Direction
A28: Direction | B28: Trades | C28: Win % | D28: Total P&L | E28: Expectancy
A29: Long | B29: 31 | C29: 55% | D29: 2443 | E29: 78.81
A30: Short | B30: 20 | C30: 50% | D30: -950.5 | E30: -47.53
A32: By Hour
A33: Hour | B33: Trades | C33: Win % | D33: Total P&L | E33: Expectancy
A34: 08:00 | B34: 1 | C34: 0% | D34: -57 | E34: -57
A35: 09:00 | B35: 11 | C35: 82% | D35: 1866.5 | E35: 169.68
A36: 10:00 | B36: 8 | C36: 38% | D36: -212.5 | E36: -26.56
A37: 11:00 | B37: 6 | C37: 50% | D37: 94.5 | E37: 15.75
A38: 12:00 | B38: 4 | C38: 100% | D38: 151 | E38: 37.75
A39: 14:00 | B39: 2 | C39: 0% | D39: -402 | E39: -201
A40: 15:00 | B40: 1 | C40: 0% | D40: -120 | E40: -120
A41: 19:00 | B41: 6 | C41: 50% | D41: -1552 | E41: -258.67
A42: 20:00 | B42: 3 | C42: 67% | D42: 538 | E42: 179.33
A43: 21:00 | B43: 1 | C43: 100% | D43: 190 | E43: 190
A44: 22:00 | B44: 4 | C44: 25% | D44: 1836 | E44: 459
...

Sheet AI Suggestions
A1: Claude AI Coaching
A3: ## Overall Assessment
A4: 51 trades over Aug 11-23, net **+$1,492** — but a profit factor of just **1.25** and **+$29/trade** expectancy. You're net green, yet the edge is thin and lopsided: nearly all your profit comes from longs and the 9 AM hour, while your short side and your overnight sessions actively bleed. Win rate 53%, avg win $273 vs avg loss $245, max drawdown **-$1,750**, worst streak 4 losses. The headline profit is really "great mornings paying for bad nights."
A6: ## What's Working
A7: - **Longs are your edge:** +$2,443 across 31 longs (55% win, +$79/trade). This is essentially your entire P&L.
A8: - **The 9 AM hour is elite:** +$1,867 over 11 trades at **82% win rate** (+$170/trade). Your single best, most repeatable window.
A9: - **Thursday (+$973) and Friday (+$648, 86% win)** are your strongest days.
A10: - When you trade small size in the morning, you are clearly, consistently profitable.
A12: ## Behavioral Patterns & Leaks
A13: - **Your short side is a net loser: -$951 over 20 shorts** (-$47/trade) despite a 50% win rate — your short losses badly outweigh your short wins. Had you simply not shorted, you'd be up ~$2,443.
A14: - **Overnight sessions destroy capital:** 19:00 **-$1,552**, 23:00 **-$840**, 10:00 -$213 — roughly **-$2,600** from three hours, mostly thin-liquidity late sessions.
A15: - **Overtrading & revenge spirals:** 11 trades on 8/11 and 9 on 8/12, with **8 flagged revenge trades** (entered 4-14 min after a loss, often up-sized). The 8/11 late-night run (19:00-23:00) has every tilt fingerprint: a position flip, size jumping to 10-30 lots, and back-to-back losses.
... A31: 3. **Install a daily circuit breaker: stop after 2 losses or 6 trades.** The 8/11-8/12 overtrading and 8 revenge entries are textbook tilt; a hard daily loss/trade cap would have prevented most of your -$1,750 drawdown.
