Workbook

Sheet Trade Tracker - Eval
A1: ZTH | B1: Date | C1: Time | D1: Asset Traded | E1: Direction | F1: Entry Price | G1: Exit Price | H1: Position Size | I1: Stop Loss | J1: Take Profit | K1: RR Targeted | L1: RR Realized | M1: Win/Loss | N1: P&L Amount | O1: P&L % | P1: Cumulative P&L | Q1: Trade Setup | R1: Notes | S1: Intrument Level | T1: Level Screenshot | U1: Trade Screenshot | V1: Mistakes | W1: Rules | X1: Market Conditions | Y1: Emotion Before Trade | Z1: Process | AA1: Learning
A2: 7 | B2: 46251 | C2: 0.41319444 | D2: MNQ | E2: Long | F2: 30240.75 | G2: 30220 | H2: 3 | I2: 30220.75 | J2: 30280.75 | K2: =IF(AND(I2<>"",J2<>"",F2<>""), (J2-F2)/(F2-I2), "") | L2: =IF(AND(F2<>"",G2<>"",I2<>""), (G2-F2)/(F2-I2), "") | M2: =IF(N2>0,"Win",IF(N2<0,"Loss","")) | N2: =IF(AND(F2<>"",G2<>"",H2<>"",D2<>""), IF(E2="Long", (G2-F2)*H2*VLOOKUP(D2,Multipliers!A:B,2,FALSE), (F2-G2)*H2*VLOOKUP(D2,Multipliers!A:B,2,FALSE)), "") | O2: =IF(AND(N2<>"",F2<>"",H2<>"",D2<>""), N2/(F2*H2*VLOOKUP(D2,Multipliers!A:B,2,FALSE)), "") | P2: =N2 | Q2: Break and Retest | S2: MNQ | T2: https://www.tradingview.com/x/ygjyjXNE/ | U2: https://www.tradingview.com/x/pqKL41ZW/ | V2: Cut winner early, Overtraded
A3: 8 | B3: 46251 | C3: 0.42291667 | D3: MGC | E3: Long | F3: 4461.4 | G3: 4473.4 | H3: 2 | I3: 4455.4 | J3: 4473.4 | K3: =IF(AND(I3<>"",J3<>"",F3<>""), (J3-F3)/(F3-I3), "") | L3: =IF(AND(F3<>"",G3<>"",I3<>""), (G3-F3)/(F3-I3), "") | M3: =IF(N3>0,"Win",IF(N3<0,"Loss","")) | N3: =IF(AND(F3<>"",G3<>"",H3<>"",D3<>""), IF(E3="Long", (G3-F3)*H3*VLOOKUP(D3,Multipliers!A:B,2,FALSE), (F3-G3)*H3*VLOOKUP(D3,Multipliers!A:B,2,FALSE)), "") | O3: =IF(AND(N3<>"",F3<>"",H3<>"",D3<>""), N3/(F3*H3*VLOOKUP(D3,Multipliers!A:B,2,FALSE)), "") | P3: =P2+N3 | Q3: Break and Retest | S3: MGC | T3: https://www.tradingview.com/x/soX7jXbm/ | U3: https://www.tradingview.com/x/Hz1BKRjK/ | V3: Oversized, Overtraded
A4: 9 | B4: 46251 | C4: 0.49375 | D4: MNQ | E4: Short | F4: 30237.75 | G4: 30221.5 | H4: 3 | I4: 30257.75 | J4: 30221.5 | K4: =IF(AND(I4<>"",J4<>"",F4<>""), (J4-F4)/(F4-I4), "") | L4: =IF(AND(F4<>"",G4<>"",I4<>""), (G4-F4)/(F4-I4), "") | M4: =IF(N4>0,"Win",IF(N4<0,"Loss","")) | N4: =IF(AND(F4<>"",G4<>"",H4<>"",D4<>""), IF(E4="Long", (G4-F4)*H4*VLOOKUP(D4,Multipliers!A:B,2,FALSE), (F4-G4)*H4*VLOOKUP(D4,Multipliers!A:B,2,FALSE)), "") | O4: =IF(AND(N4<>"",F4<>"",H4<>"",D4<>""), N4/(F4*H4*VLOOKUP(D4,Multipliers!A:B,2,FALSE)), "") | P4: =P3+N4 | Q4: Break and Retest | S4: MNQ | U4: https://www.tradingview.com/x/pqKL41ZW/ | V4: Oversized, Overtraded
A5: 10 | B5: 46245 | C5: 0.81082176 | D5: MGC | E5: Long | F5: 4429.1 | G5: 4430.1 | H5: 3 | I5: 4423.4 | J5: 4431.5 | K5: =IF(AND(I5<>"",J5<>"",F5<>""), (J5-F5)/(F5-I5), "") | L5: =IF(AND(F5<>"",G5<>"",I5<>""), (G5-F5)/(F5-I5), "") | M5: =IF(N5>0,"Win",IF(N5<0,"Loss","")) | N5: =IF(AND(F5<>"",G5<>"",H5<>"",D5<>""), IF(E5="Long", (G5-F5)*H5*VLOOKUP(D5,Multipliers!A:B,2,FALSE), (F5-G5)*H5*VLOOKUP(D5,Multipliers!A:B,2,FALSE)), "") | O5: =IF(AND(N5<>"",F5<>"",H5<>"",D5<>""), N5/(F5*H5*VLOOKUP(D5,Multipliers!A:B,2,FALSE)), "") | P5: =P4+N5 | Q5: Break and Retest | R5: Imported from Tradovate | S5: MGC | V5: Oversized, Revenge trade, Overtraded
A6: 11 | B6: 46245 | C6: 0.81194444 | D6: MGC | E6: Short | F6: 4431.6 | G6: 4430.5 | H6: 10 | J6: 4430.5 | K6: =IF(AND(I6<>"",J6<>"",F6<>""), (J6-F6)/(F6-I6), "") | L6: =IF(AND(F6<>"",G6<>"",I6<>""), (G6-F6)/(F6-I6), "") | M6: =IF(N6>0,"Win",IF(N6<0,"Loss","")) | N6: =IF(AND(F6<>"",G6<>"",H6<>"",D6<>""), IF(E6="Long", (G6-F6)*H6*VLOOKUP(D6,Multipliers!A:B,2,FALSE), (F6-G6)*H6*VLOOKUP(D6,Multipliers!A:B,2,FALSE)), "") | O6: =IF(AND(N6<>"",F6<>"",H6<>"",D6<>""), N6/(F6*H6*VLOOKUP(D6,Multipliers!A:B,2,FALSE)), "") | P6: =P5+N6 | Q6: Break and Retest | R6: Imported from Tradovate | S6: MGC | V6: Oversized, Overtraded
A7: 12 | B7: 46245 | C7: 0.81283565 | D7: MGC | E7: Long | F7: 4430.6 | G7: 4426.2 | H7: 10 | I7: 4423.4 | J7: 4431.5 | K7: =IF(AND(I7<>"",J7<>"",F7<>""), (J7-F7)/(F7-I7), "") | L7: =IF(AND(F7<>"",G7<>"",I7<>""), (G7-F7)/(F7-I7), "") | M7: =IF(N7>0,"Win",IF(N7<0,"Loss","")) | N7: =IF(AND(F7<>"",G7<>"",H7<>"",D7<>""), IF(E7="Long", (G7-F7)*H7*VLOOKUP(D7,Multipliers!A:B,2,FALSE), (F7-G7)*H7*VLOOKUP(D7,Multipliers!A:B,2,FALSE)), "") | O7: =IF(AND(N7<>"",F7<>"",H7<>"",D7<>""), N7/(F7*H7*VLOOKUP(D7,Multipliers!A:B,2,FALSE)), "") | P7: =P6+N7 | Q7: Break and Retest | R7: Imported from Tradovate | S7: MGC | V7: Oversized, Overtraded
A8: 13 | B8: 46245 | C8: 0.81564815 | D8: MGC | E8: Short | F8: 4427 | G8: 4440.1 | H8: 10 | J8: 4426.8 | K8: =IF(AND(I8<>"",J8<>"",F8<>""), (J8-F8)/(F8-I8), "") | L8: =IF(AND(F8<>"",G8<>"",I8<>""), (G8-F8)/(F8-I8), "") | M8: =IF(N8>0,"Win",IF(N8<0,"Loss","")) | N8: =IF(AND(F8<>"",G8<>"",H8<>"",D8<>""), IF(E8="Long", (G8-F8)*H8*VLOOKUP(D8,Multipliers!A:B,2,FALSE), (F8-G8)*H8*VLOOKUP(D8,Multipliers!A:B,2,FALSE)), "") | O8: =IF(AND(N8<>"",F8<>"",H8<>"",D8<>""), N8/(F8*H8*VLOOKUP(D8,Multipliers!A:B,2,FALSE)), "") | P8: =P7+N8 | Q8: Break and Retest | R8: Imported from Tradovate | S8: MGC | V8: Oversized, Overtraded
A9: 14 | B9: 46245 | C9: 0.85517361 | D9: MGC | E9: Long | F9: 4440.1 | G9: 4443.8 | H9: 10 | J9: 4443.8 | K9: =IF(AND(I9<>"",J9<>"",F9<>""), (J9-F9)/(F9-I9), "") | L9: =IF(AND(F9<>"",G9<>"",I9<>""), (G9-F9)/(F9-I9), "") | M9: =IF(N9>0,"Win",IF(N9<0,"Loss","")) | N9: =IF(AND(F9<>"",G9<>"",H9<>"",D9<>""), IF(E9="Long", (G9-F9)*H9*VLOOKUP(D9,Multipliers!A:B,2,FALSE), (F9-G9)*H9*VLOOKUP(D9,Multipliers!A:B,2,FALSE)), "") | O9: =IF(AND(N9<>"",F9<>"",H9<>"",D9<>""), N9/(F9*H9*VLOOKUP(D9,Multipliers!A:B,2,FALSE)), "") | P9: =P8+N9 | Q9: Break and Retest | R9: Imported from Tradovate | S9: MGC | V9: Oversized, Overtraded
A10: 15 | B10: 46245 | C10: 0.88615741 | D10: MGC | E10: Long | F10: 4457.1667 | G10: 4457.8 | H10: 30 | J10: 4472.1 | K10: =IF(AND(I10<>"",J10<>"",F10<>""), (J10-F10)/(F10-I10), "") | L10: =IF(AND(F10<>"",G10<>"",I10<>""), (G10-F10)/(F10-I10), "") | M10: =IF(N10>0,"Win",IF(N10<0,"Loss","")) | N10: =IF(AND(F10<>"",G10<>"",H10<>"",D10<>""), IF(E10="Long", (G10-F10)*H10*VLOOKUP(D10,Multipliers!A:B,2,FALSE), (F10-G10)*H10*VLOOKUP(D10,Multipliers!A:B,2,FALSE)), "") | O10: =IF(AND(N10<>"",F10<>"",H10<>"",D10<>""), N10/(F10*H10*VLOOKUP(D10,Multipliers!A:B,2,FALSE)), "") | P10: =P9+N10 | Q10: Break and Retest | R10: Imported from Tradovate | S10: MGC | V10: Oversized, Overtraded
A11: 16 | B11: 46245 | C11: 0.9446412 | D11: MGC | E11: Long | F11: 4461.8 | G11: 4469 | H11: 30 | J11: 4474.1 | K11: =IF(AND(I11<>"",J11<>"",F11<>""), (J11-F11)/(F11-I11), "") | L11: =IF(AND(F11<>"",G11<>"",I11<>""), (G11-F11)/(F11-I11), "") | M11: =IF(N11>0,"Win",IF(N11<0,"Loss","")) | N11: =IF(AND(F11<>"",G11<>"",H11<>"",D11<>""), IF(E11="Long", (G11-F11)*H11*VLOOKUP(D11,Multipliers!A:B,2,FALSE), (F11-G11)*H11*VLOOKUP(D11,Multipliers!A:B,2,FALSE)), "") | O11: =IF(AND(N11<>"",F11<>"",H11<>"",D11<>""), N11/(F11*H11*VLOOKUP(D11,Multipliers!A:B,2,FALSE)), "") | P11: =P10+N11 | Q11: Break and Retest | R11: Imported from Tradovate | S11: MGC | V11: Oversized, Revenge trade, Overtraded
A12: 17 | B12: 46245 | C12: 0.95865741 | D12: MGC | E12: Long | F12: 4472.3 | G12: 4470.9 | H12: 20 | J12: 4475.9 | K12: =IF(AND(I12<>"",J12<>"",F12<>""), (J12-F12)/(F12-I12), "") | L12: =IF(AND(F12<>"",G12<>"",I12<>""), (G12-F12)/(F12-I12), "") | M12: =IF(N12>0,"Win",IF(N12<0,"Loss","")) | N12: =IF(AND(F12<>"",G12<>"",H12<>"",D12<>""), IF(E12="Long", (G12-F12)*H12*VLOOKUP(D12,Multipliers!A:B,2,FALSE), (F12-G12)*H12*VLOOKUP(D12,Multipliers!A:B,2,FALSE)), "") | O12: =IF(AND(N12<>"",F12<>"",H12<>"",D12<>""), N12/(F12*H12*VLOOKUP(D12,Multipliers!A:B,2,FALSE)), "") | P12: =P11+N12 | Q12: Break and Retest | R12: Imported from Tradovate | S12: MGC | V12: Oversized, Revenge trade, Overtraded
A13: 18 | B13: 46245 | C13: 0.96665509 | D13: MGC | E13: Long | F13: 4473.9 | G13: 4464.8 | H13: 10 | K13: =IF(AND(I13<>"",J13<>"",F13<>""), (J13-F13)/(F13-I13), "") | L13: =IF(AND(F13<>"",G13<>"",I13<>""), (G13-F13)/(F13-I13), "") | M13: =IF(N13>0,"Win",IF(N13<0,"Loss","")) | N13: =IF(AND(F13<>"",G13<>"",H13<>"",D13<>""), IF(E13="Long", (G13-F13)*H13*VLOOKUP(D13,Multipliers!A:B,2,FALSE), (F13-G13)*H13*VLOOKUP(D13,Multipliers!A:B,2,FALSE)), "") | O13: =IF(AND(N13<>"",F13<>"",H13<>"",D13<>""), N13/(F13*H13*VLOOKUP(D13,Multipliers!A:B,2,FALSE)), "") | P13: =P12+N13 | Q13: Break and Retest | R13: Imported from Tradovate | S13: MGC | V13: Overtraded
A14: 19 | B14: 46245 | C14: 0.97626157 | D14: MGC | E14: Long | F14: 4467.3 | G14: 4465.9 | H14: 10 | K14: =IF(AND(I14<>"",J14<>"",F14<>""), (J14-F14)/(F14-I14), "") | L14: =IF(AND(F14<>"",G14<>"",I14<>""), (G14-F14)/(F14-I14), "") | M14: =IF(N14>0,"Win",IF(N14<0,"Loss","")) | N14: =IF(AND(F14<>"",G14<>"",H14<>"",D14<>""), IF(E14="Long", (G14-F14)*H14*VLOOKUP(D14,Multipliers!A:B,2,FALSE), (F14-G14)*H14*VLOOKUP(D14,Multipliers!A:B,2,FALSE)), "") | O14: =IF(AND(N14<>"",F14<>"",H14<>"",D14<>""), N14/(F14*H14*VLOOKUP(D14,Multipliers!A:B,2,FALSE)), "") | P14: =P13+N14 | Q14: Break and Retest | R14: Imported from Tradovate | S14: MGC | V14: Oversized, Overtraded
A15: 20 | B15: 46245 | C15: 0.9837037 | D15: MGC | E15: Short | F15: 4461.05 | G15: 4458.6 | H15: 20 | J15: 4458.6 | K15: =IF(AND(I15<>"",J15<>"",F15<>""), (J15-F15)/(F15-I15), "") | L15: =IF(AND(F15<>"",G15<>"",I15<>""), (G15-F15)/(F15-I15), "") | M15: =IF(N15>0,"Win",IF(N15<0,"Loss","")) | N15: =IF(AND(F15<>"",G15<>"",H15<>"",D15<>""), IF(E15="Long", (G15-F15)*H15*VLOOKUP(D15,Multipliers!A:B,2,FALSE), (F15-G15)*H15*VLOOKUP(D15,Multipliers!A:B,2,FALSE)), "") | O15: =IF(AND(N15<>"",F15<>"",H15<>"",D15<>""), N15/(F15*H15*VLOOKUP(D15,Multipliers!A:B,2,FALSE)), "") | P15: =P14+N15 | Q15: Break and Retest | R15: Imported from Tradovate | S15: MGC | V15: Overtraded
A16: 21 | B16: 46246 | C16: 0.38358796 | D16: MNQ | E16: Long | F16: 29931.25 | G16: 29936 | H16: 5 | J16: 29936 | K16: =IF(AND(I16<>"",J16<>"",F16<>""), (J16-F16)/(F16-I16), "") | L16: =IF(AND(F16<>"",G16<>"",I16<>""), (G16-F16)/(F16-I16), "") | M16: =IF(N16>0,"Win",IF(N16<0,"Loss","")) | N16: =IF(AND(F16<>"",G16<>"",H16<>"",D16<>""), IF(E16="Long", (G16-F16)*H16*VLOOKUP(D16,Multipliers!A:B,2,FALSE), (F16-G16)*H16*VLOOKUP(D16,Multipliers!A:B,2,FALSE)), "") | O16: =IF(AND(N16<>"",F16<>"",H16<>"",D16<>""), N16/(F16*H16*VLOOKUP(D16,Multipliers!A:B,2,FALSE)), "") | P16: =P15+N16 | Q16: Break and Retest | R16: Imported from Tradovate | S16: MNQ | V16: Oversized, Overtraded
A17: 22 | B17: 46246 | C17: 0.39325231 | D17: MGC | E17: Short | F17: 4475.7 | G17: 4474 | H17: 10 | J17: 4474 | K17: =IF(AND(I17<>"",J17<>"",F17<>""), (J17-F17)/(F17-I17), "") | L17: =IF(AND(F17<>"",G17<>"",I17<>""), (G17-F17)/(F17-I17), "") | M17: =IF(N17>0,"Win",IF(N17<0,"Loss","")) | N17: =IF(AND(F17<>"",G17<>"",H17<>"",D17<>""), IF(E17="Long", (G17-F17)*H17*VLOOKUP(D17,Multipliers!A:B,2,FALSE), (F17-G17)*H17*VLOOKUP(D17,Multipliers!A:B,2,FALSE)), "") | O17: =IF(AND(N17<>"",F17<>"",H17<>"",D17<>""), N17/(F17*H17*VLOOKUP(D17,Multipliers!A:B,2,FALSE)), "") | P17: =P16+N17 | Q17: Break and Retest | R17: Imported from Tradovate | S17: MGC | V17: Overtraded
A18: 23 | B18: 46246 | C18: 0.40153935 | D18: MNQ | E18: Short | F18: 29915.75 | G18: 29881 | H18: 1 | J18: 29881 | K18: =IF(AND(I18<>"",J18<>"",F18<>""), (J18-F18)/(F18-I18), "") | L18: =IF(AND(F18<>"",G18<>"",I18<>""), (G18-F18)/(F18-I18), "") | M18: =IF(N18>0,"Win",IF(N18<0,"Loss","")) | N18: =IF(AND(F18<>"",G18<>"",H18<>"",D18<>""), IF(E18="Long", (G18-F18)*H18*VLOOKUP(D18,Multipliers!A:B,2,FALSE), (F18-G18)*H18*VLOOKUP(D18,Multipliers!A:B,2,FALSE)), "") | O18: =IF(AND(N18<>"",F18<>"",H18<>"",D18<>""), N18/(F18*H18*VLOOKUP(D18,Multipliers!A:B,2,FALSE)), "") | P18: =P17+N18 | Q18: Break and Retest | R18: Imported from Tradovate | S18: MNQ | V18: Overtraded
A19: 24 | B19: 46246 | C19: 0.4109838 | D19: MGC | E19: Long | F19: 4490 | G19: 4485.4 | H19: 10 | K19: =IF(AND(I19<>"",J19<>"",F19<>""), (J19-F19)/(F19-I19), "") | L19: =IF(AND(F19<>"",G19<>"",I19<>""), (G19-F19)/(F19-I19), "") | M19: =IF(N19>0,"Win",IF(N19<0,"Loss","")) | N19: =IF(AND(F19<>"",G19<>"",H19<>"",D19<>""), IF(E19="Long", (G19-F19)*H19*VLOOKUP(D19,Multipliers!A:B,2,FALSE), (F19-G19)*H19*VLOOKUP(D19,Multipliers!A:B,2,FALSE)), "") | O19: =IF(AND(N19<>"",F19<>"",H19<>"",D19<>""), N19/(F19*H19*VLOOKUP(D19,Multipliers!A:B,2,FALSE)), "") | P19: =P18+N19 | Q19: Break and Retest | R19: Imported from Tradovate | S19: MGC | V19: Overtraded
A20: 25 | B20: 46246 | C20: 0.45519676 | D20: MNQ | E20: Long | F20: 29863 | G20: 29878.5 | H20: 3 | I20: 29833 | J20: 29878.5 | K20: =IF(AND(I20<>"",J20<>"",F20<>""), (J20-F20)/(F20-I20), "") | L20: =IF(AND(F20<>"",G20<>"",I20<>""), (G20-F20)/(F20-I20), "") | M20: =IF(N20>0,"Win",IF(N20<0,"Loss","")) | N20: =IF(AND(F20<>"",G20<>"",H20<>"",D20<>""), IF(E20="Long", (G20-F20)*H20*VLOOKUP(D20,Multipliers!A:B,2,FALSE), (F20-G20)*H20*VLOOKUP(D20,Multipliers!A:B,2,FALSE)), "") | O20: =IF(AND(N20<>"",F20<>"",H20<>"",D20<>""), N20/(F20*H20*VLOOKUP(D20,Multipliers!A:B,2,FALSE)), "") | P20: =P19+N20 | Q20: Break and Retest | R20: Imported from Tradovate | S20: MNQ | V20: Blew stop, Overtraded
A21: 26 | B21: 46246 | C21: 0.47391204 | D21: MNQ | E21: Long | F21: 29854 | G21: 29879.75 | H21: 3 | I21: 29834.5 | J21: 29894.5 | K21: =IF(AND(I21<>"",J21<>"",F21<>""), (J21-F21)/(F21-I21), "") | L21: =IF(AND(F21<>"",G21<>"",I21<>""), (G21-F21)/(F21-I21), "") | M21: =IF(N21>0,"Win",IF(N21<0,"Loss","")) | N21: =IF(AND(F21<>"",G21<>"",H21<>"",D21<>""), IF(E21="Long", (G21-F21)*H21*VLOOKUP(D21,Multipliers!A:B,2,FALSE), (F21-G21)*H21*VLOOKUP(D21,Multipliers!A:B,2,FALSE)), "") | O21: =IF(AND(N21<>"",F21<>"",H21<>"",D21<>""), N21/(F21*H21*VLOOKUP(D21,Multipliers!A:B,2,FALSE)), "") | P21: =P20+N21 | Q21: Break and Retest | R21: Imported from Tradovate | S21: MNQ | V21: Overtraded
A22: 27 | B22: 46246 | C22: 0.480625 | D22: MNQ | E22: Long | F22: 29855.75 | G22: 29833 | H22: 3 | I22: 29834.5 | J22: 29894.5 | K22: =IF(AND(I22<>"",J22<>"",F22<>""), (J22-F22)/(F22-I22), "") | L22: =IF(AND(F22<>"",G22<>"",I22<>""), (G22-F22)/(F22-I22), "") | M22: =IF(N22>0,"Win",IF(N22<0,"Loss","")) | N22: =IF(AND(F22<>"",G22<>"",H22<>"",D22<>""), IF(E22="Long", (G22-F22)*H22*VLOOKUP(D22,Multipliers!A:B,2,FALSE), (F22-G22)*H22*VLOOKUP(D22,Multipliers!A:B,2,FALSE)), "") | O22: =IF(AND(N22<>"",F22<>"",H22<>"",D22<>""), N22/(F22*H22*VLOOKUP(D22,Multipliers!A:B,2,FALSE)), "") | P22: =P21+N22 | Q22: Break and Retest | R22: Imported from Tradovate | S22: MNQ
A23: 28 | B23: 46246 | C23: 0.49825231 | D23: MNQ | E23: Short | F23: 29838.25 | G23: 29862.25 | H23: 3 | I23: 29858.5 | J23: 29823.5 | K23: =IF(AND(I23<>"",J23<>"",F23<>""), (J23-F23)/(F23-I23), "") | L23: =IF(AND(F23<>"",G23<>"",I23<>""), (G23-F23)/(F23-I23), "") | M23: =IF(N23>0,"Win",IF(N23<0,"Loss","")) | N23: =IF(AND(F23<>"",G23<>"",H23<>"",D23<>""), IF(E23="Long", (G23-F23)*H23*VLOOKUP(D23,Multipliers!A:B,2,FALSE), (F23-G23)*H23*VLOOKUP(D23,Multipliers!A:B,2,FALSE)), "") | O23: =IF(AND(N23<>"",F23<>"",H23<>"",D23<>""), N23/(F23*H23*VLOOKUP(D23,Multipliers!A:B,2,FALSE)), "") | P23: =P22+N23 | Q23: Break and Retest | R23: Imported from Tradovate | S23: MNQ
A24: 29 | B24: 46246 | C24: 0.59178241 | D24: MGC | E24: Short | F24: 4465.4 | G24: 4471.9 | H24: 3 | I24: 4471.8 | J24: 4458.5 | K24: =IF(AND(I24<>"",J24<>"",F24<>""), (J24-F24)/(F24-I24), "") | L24: =IF(AND(F24<>"",G24<>"",I24<>""), (G24-F24)/(F24-I24), "") | M24: =IF(N24>0,"Win",IF(N24<0,"Loss","")) | N24: =IF(AND(F24<>"",G24<>"",H24<>"",D24<>""), IF(E24="Long", (G24-F24)*H24*VLOOKUP(D24,Multipliers!A:B,2,FALSE), (F24-G24)*H24*VLOOKUP(D24,Multipliers!A:B,2,FALSE)), "") | O24: =IF(AND(N24<>"",F24<>"",H24<>"",D24<>""), N24/(F24*H24*VLOOKUP(D24,Multipliers!A:B,2,FALSE)), "") | P24: =P23+N24 | Q24: Break and Retest | R24: Imported from Tradovate | S24: MGC
A25: 30 | B25: 46247 | C25: 0.36866898 | D25: MGC | E25: Long | F25: 4450.95 | G25: 4448.1 | H25: 2 | I25: 4444.4 | J25: 4451.8 | K25: =IF(AND(I25<>"",J25<>"",F25<>""), (J25-F25)/(F25-I25), "") | L25: =IF(AND(F25<>"",G25<>"",I25<>""), (G25-F25)/(F25-I25), "") | M25: =IF(N25>0,"Win",IF(N25<0,"Loss","")) | N25: =IF(AND(F25<>"",G25<>"",H25<>"",D25<>""), IF(E25="Long", (G25-F25)*H25*VLOOKUP(D25,Multipliers!A:B,2,FALSE), (F25-G25)*H25*VLOOKUP(D25,Multipliers!A:B,2,FALSE)), "") | O25: =IF(AND(N25<>"",F25<>"",H25<>"",D25<>""), N25/(F25*H25*VLOOKUP(D25,Multipliers!A:B,2,FALSE)), "") | P25: =P24+N25 | Q25: Break and Retest | R25: Imported from Tradovate | S25: MGC
A26: 31 | B26: 46247 | C26: 0.40733796 | D26: MNQ | E26: Long | F26: 30089.5 | G26: 30127 | H26: 5 | I26: 30067 | J26: 30127 | K26: =IF(AND(I26<>"",J26<>"",F26<>""), (J26-F26)/(F26-I26), "") | L26: =IF(AND(F26<>"",G26<>"",I26<>""), (G26-F26)/(F26-I26), "") | M26: =IF(N26>0,"Win",IF(N26<0,"Loss","")) | N26: =IF(AND(F26<>"",G26<>"",H26<>"",D26<>""), IF(E26="Long", (G26-F26)*H26*VLOOKUP(D26,Multipliers!A:B,2,FALSE), (F26-G26)*H26*VLOOKUP(D26,Multipliers!A:B,2,FALSE)), "") | O26: =IF(AND(N26<>"",F26<>"",H26<>"",D26<>""), N26/(F26*H26*VLOOKUP(D26,Multipliers!A:B,2,FALSE)), "") | P26: =P25+N26 | Q26: Break and Retest | R26: Imported from Tradovate | S26: MNQ | V26: Revenge trade
A27: 32 | B27: 46247 | C27: 0.47510417 | D27: MGC | E27: Short | F27: 4427.5 | G27: 4418 | H27: 3 | J27: 4418 | K27: =IF(AND(I27<>"",J27<>"",F27<>""), (J27-F27)/(F27-I27), "") | L27: =IF(AND(F27<>"",G27<>"",I27<>""), (G27-F27)/(F27-I27), "") | M27: =IF(N27>0,"Win",IF(N27<0,"Loss","")) | N27: =IF(AND(F27<>"",G27<>"",H27<>"",D27<>""), IF(E27="Long", (G27-F27)*H27*VLOOKUP(D27,Multipliers!A:B,2,FALSE), (F27-G27)*H27*VLOOKUP(D27,Multipliers!A:B,2,FALSE)), "") | O27: =IF(AND(N27<>"",F27<>"",H27<>"",D27<>""), N27/(F27*H27*VLOOKUP(D27,Multipliers!A:B,2,FALSE)), "") | P27: =P26+N27 | Q27: Break and Retest | R27: Imported from Tradovate | S27: MGC
A28: 33 | B28: 46247 | C28: 0.95162037 | D28: MGC | E28: Long | F28: 4371.8 | G28: 4369.6 | H28: 3 | K28: =IF(AND(I28<>"",J28<>"",F28<>""), (J28-F28)/(F28-I28), "") | L28: =IF(AND(F28<>"",G28<>"",I28<>""), (G28-F28)/(F28-I28), "") | M28: =IF(N28>0,"Win",IF(N28<0,"Loss","")) | N28: =IF(AND(F28<>"",G28<>"",H28<>"",D28<>""), IF(E28="Long", (G28-F28)*H28*VLOOKUP(D28,Multipliers!A:B,2,FALSE), (F28-G28)*H28*VLOOKUP(D28,Multipliers!A:B,2,FALSE)), "") | O28: =IF(AND(N28<>"",F28<>"",H28<>"",D28<>""), N28/(F28*H28*VLOOKUP(D28,Multipliers!A:B,2,FALSE)), "") | P28: =P27+N28 | Q28: Break and Retest | R28: Imported from Tradovate | S28: MGC
A29: 34 | B29: 46247 | C29: 0.95800926 | D29: MGC | E29: Short | F29: 4370.5 | G29: 4377 | H29: 3 | I29: 4377 | J29: 4369.3 | K29: =IF(AND(I29<>"",J29<>"",F29<>""), (J29-F29)/(F29-I29), "") | L29: =IF(AND(F29<>"",G29<>"",I29<>""), (G29-F29)/(F29-I29), "") | M29: =IF(N29>0,"Win",IF(N29<0,"Loss","")) | N29: =IF(AND(F29<>"",G29<>"",H29<>"",D29<>""), IF(E29="Long", (G29-F29)*H29*VLOOKUP(D29,Multipliers!A:B,2,FALSE), (F29-G29)*H29*VLOOKUP(D29,Multipliers!A:B,2,FALSE)), "") | O29: =IF(AND(N29<>"",F29<>"",H29<>"",D29<>""), N29/(F29*H29*VLOOKUP(D29,Multipliers!A:B,2,FALSE)), "") | P29: =P28+N29 | Q29: Break and Retest | R29: Imported from Tradovate | S29: MGC
A30: 35 | B30: 46248 | C30: 0.40767361 | D30: MNQ | E30: Long | F30: 30233 | G30: 30255.75 | H30: 3 | J30: 30272 | K30: =IF(AND(I30<>"",J30<>"",F30<>""), (J30-F30)/(F30-I30), "") | L30: =IF(AND(F30<>"",G30<>"",I30<>""), (G30-F30)/(F30-I30), "") | M30: =IF(N30>0,"Win",IF(N30<0,"Loss","")) | N30: =IF(AND(F30<>"",G30<>"",H30<>"",D30<>""), IF(E30="Long", (G30-F30)*H30*VLOOKUP(D30,Multipliers!A:B,2,FALSE), (F30-G30)*H30*VLOOKUP(D30,Multipliers!A:B,2,FALSE)), "") | O30: =IF(AND(N30<>"",F30<>"",H30<>"",D30<>""), N30/(F30*H30*VLOOKUP(D30,Multipliers!A:B,2,FALSE)), "") | P30: =P29+N30 | Q30: Break and Retest | R30: Imported from Tradovate | S30: MNQ
A31: 36 | B31: 46248 | C31: 0.41525463 | D31: MNQ | E31: Long | F31: 30221 | G31: 30225.5 | H31: 3 | I31: 30201 | J31: 30225.5 | K31: =IF(AND(I31<>"",J31<>"",F31<>""), (J31-F31)/(F31-I31), "") | L31: =IF(AND(F31<>"",G31<>"",I31<>""), (G31-F31)/(F31-I31), "") | M31: =IF(N31>0,"Win",IF(N31<0,"Loss","")) | N31: =IF(AND(F31<>"",G31<>"",H31<>"",D31<>""), IF(E31="Long", (G31-F31)*H31*VLOOKUP(D31,Multipliers!A:B,2,FALSE), (F31-G31)*H31*VLOOKUP(D31,Multipliers!A:B,2,FALSE)), "") | O31: =IF(AND(N31<>"",F31<>"",H31<>"",D31<>""), N31/(F31*H31*VLOOKUP(D31,Multipliers!A:B,2,FALSE)), "") | P31: =P30+N31 | Q31: Break and Retest | R31: Imported from Tradovate | S31: MNQ
A32: 37 | B32: 46248 | C32: 0.49888889 | D32: MNQ | E32: Short | F32: 30072.5 | G32: 30099.5 | H32: 3 | I32: 30099.5 | J32: 30058.25 | K32: =IF(AND(I32<>"",J32<>"",F32<>""), (J32-F32)/(F32-I32), "") | L32: =IF(AND(F32<>"",G32<>"",I32<>""), (G32-F32)/(F32-I32), "") | M32: =IF(N32>0,"Win",IF(N32<0,"Loss","")) | N32: =IF(AND(F32<>"",G32<>"",H32<>"",D32<>""), IF(E32="Long", (G32-F32)*H32*VLOOKUP(D32,Multipliers!A:B,2,FALSE), (F32-G32)*H32*VLOOKUP(D32,Multipliers!A:B,2,FALSE)), "") | O32: =IF(AND(N32<>"",F32<>"",H32<>"",D32<>""), N32/(F32*H32*VLOOKUP(D32,Multipliers!A:B,2,FALSE)), "") | P32: =P31+N32 | Q32: Break and Retest | R32: Imported from Tradovate | S32: MNQ
A33: 38 | B33: 46248 | C33: 0.5287037 | D33: MNQ | E33: Short | F33: 30068.5 | G33: 30064 | H33: 3 | I33: 30088.5 | J33: 30064 | K33: =IF(AND(I33<>"",J33<>"",F33<>""), (J33-F33)/(F33-I33), "") | L33: =IF(AND(F33<>"",G33<>"",I33<>""), (G33-F33)/(F33-I33), "") | M33: =IF(N33>0,"Win",IF(N33<0,"Loss","")) | N33: =IF(AND(F33<>"",G33<>"",H33<>"",D33<>""), IF(E33="Long", (G33-F33)*H33*VLOOKUP(D33,Multipliers!A:B,2,FALSE), (F33-G33)*H33*VLOOKUP(D33,Multipliers!A:B,2,FALSE)), "") | O33: =IF(AND(N33<>"",F33<>"",H33<>"",D33<>""), N33/(F33*H33*VLOOKUP(D33,Multipliers!A:B,2,FALSE)), "") | P33: =P32+N33 | Q33: Break and Retest | R33: Imported from Tradovate | S33: MNQ
A34: 39 | B34: 46248 | C34: 0.53212963 | D34: MNQ | E34: Long | F34: 30067 | G34: 30071.25 | H34: 5 | I34: 30047.75 | J34: 30074.5 | K34: =IF(AND(I34<>"",J34<>"",F34<>""), (J34-F34)/(F34-I34), "") | L34: =IF(AND(F34<>"",G34<>"",I34<>""), (G34-F34)/(F34-I34), "") | M34: =IF(N34>0,"Win",IF(N34<0,"Loss","")) | N34: =IF(AND(F34<>"",G34<>"",H34<>"",D34<>""), IF(E34="Long", (G34-F34)*H34*VLOOKUP(D34,Multipliers!A:B,2,FALSE), (F34-G34)*H34*VLOOKUP(D34,Multipliers!A:B,2,FALSE)), "") | O34: =IF(AND(N34<>"",F34<>"",H34<>"",D34<>""), N34/(F34*H34*VLOOKUP(D34,Multipliers!A:B,2,FALSE)), "") | P34: =P33+N34 | Q34: Break and Retest | R34: Imported from Tradovate | S34: MNQ
A35: 40 | B35: 46248 | C35: 0.53502315 | D35: MNQ | E35: Long | F35: 30064.5 | G35: 30068 | H35: 5 | J35: 30074.5 | K35: =IF(AND(I35<>"",J35<>"",F35<>""), (J35-F35)/(F35-I35), "") | L35: =IF(AND(F35<>"",G35<>"",I35<>""), (G35-F35)/(F35-I35), "") | M35: =IF(N35>0,"Win",IF(N35<0,"Loss","")) | N35: =IF(AND(F35<>"",G35<>"",H35<>"",D35<>""), IF(E35="Long", (G35-F35)*H35*VLOOKUP(D35,Multipliers!A:B,2,FALSE), (F35-G35)*H35*VLOOKUP(D35,Multipliers!A:B,2,FALSE)), "") | O35: =IF(AND(N35<>"",F35<>"",H35<>"",D35<>""), N35/(F35*H35*VLOOKUP(D35,Multipliers!A:B,2,FALSE)), "") | P35: =P34+N35 | Q35: Break and Retest | R35: Imported from Tradovate | S35: MNQ
A36: 41 | B36: 46252 | C36: 0.41706019 | D36: MGC | E36: Short | F36: 4454.7 | G36: 4460 | H36: 3 | I36: 4459.9 | J36: 4454 | K36: =IF(AND(I36<>"",J36<>"",F36<>""), (J36-F36)/(F36-I36), "") | L36: =IF(AND(F36<>"",G36<>"",I36<>""), (G36-F36)/(F36-I36), "") | M36: =IF(N36>0,"Win",IF(N36<0,"Loss","")) | N36: =IF(AND(F36<>"",G36<>"",H36<>"",D36<>""), IF(E36="Long", (G36-F36)*H36*VLOOKUP(D36,Multipliers!A:B,2,FALSE), (F36-G36)*H36*VLOOKUP(D36,Multipliers!A:B,2,FALSE)), "") | O36: =IF(AND(N36<>"",F36<>"",H36<>"",D36<>""), N36/(F36*H36*VLOOKUP(D36,Multipliers!A:B,2,FALSE)), "") | P36: =P35+N36 | Q36: Break and Retest | R36: Imported from Tradovate | S36: MGC
A37: 42 | B37: 46252 | C37: 0.42253472 | D37: MGC | E37: Long | F37: 4454.2 | G37: 4448.2 | H37: 3 | I37: 4448.2 | J37: 4467 | K37: =IF(AND(I37<>"",J37<>"",F37<>""), (J37-F37)/(F37-I37), "") | L37: =IF(AND(F37<>"",G37<>"",I37<>""), (G37-F37)/(F37-I37), "") | M37: =IF(N37>0,"Win",IF(N37<0,"Loss","")) | N37: =IF(AND(F37<>"",G37<>"",H37<>"",D37<>""), IF(E37="Long", (G37-F37)*H37*VLOOKUP(D37,Multipliers!A:B,2,FALSE), (F37-G37)*H37*VLOOKUP(D37,Multipliers!A:B,2,FALSE)), "") | O37: =IF(AND(N37<>"",F37<>"",H37<>"",D37<>""), N37/(F37*H37*VLOOKUP(D37,Multipliers!A:B,2,FALSE)), "") | P37: =P36+N37 | Q37: Break and Retest | R37: Imported from Tradovate | S37: MGC | V37: Revenge trade
A38: 43 | B38: 46252 | C38: 0.42832176 | D38: MNQ | E38: Short | F38: 29614 | G38: 29634 | H38: 2 | I38: 29634 | J38: 29574 | K38: =IF(AND(I38<>"",J38<>"",F38<>""), (J38-F38)/(F38-I38), "") | L38: =IF(AND(F38<>"",G38<>"",I38<>""), (G38-F38)/(F38-I38), "") | M38: =IF(N38>0,"Win",IF(N38<0,"Loss","")) | N38: =IF(AND(F38<>"",G38<>"",H38<>"",D38<>""), IF(E38="Long", (G38-F38)*H38*VLOOKUP(D38,Multipliers!A:B,2,FALSE), (F38-G38)*H38*VLOOKUP(D38,Multipliers!A:B,2,FALSE)), "") | O38: =IF(AND(N38<>"",F38<>"",H38<>"",D38<>""), N38/(F38*H38*VLOOKUP(D38,Multipliers!A:B,2,FALSE)), "") | P38: =P37+N38 | Q38: Break and Retest | R38: Imported from Tradovate | S38: MNQ
A39: 44 | B39: 46252 | C39: 0.43178241 | D39: MNQ | E39: Short | F39: 29607.5 | G39: 29656.75 | H39: 3 | I39: 29649 | J39: 29552 | K39: =IF(AND(I39<>"",J39<>"",F39<>""), (J39-F39)/(F39-I39), "") | L39: =IF(AND(F39<>"",G39<>"",I39<>""), (G39-F39)/(F39-I39), "") | M39: =IF(N39>0,"Win",IF(N39<0,"Loss","")) | N39: =IF(AND(F39<>"",G39<>"",H39<>"",D39<>""), IF(E39="Long", (G39-F39)*H39*VLOOKUP(D39,Multipliers!A:B,2,FALSE), (F39-G39)*H39*VLOOKUP(D39,Multipliers!A:B,2,FALSE)), "") | O39: =IF(AND(N39<>"",F39<>"",H39<>"",D39<>""), N39/(F39*H39*VLOOKUP(D39,Multipliers!A:B,2,FALSE)), "") | P39: =P38+N39 | Q39: Break and Retest | R39: Imported from Tradovate | S39: MNQ | V39: Blew stop, Revenge trade
A40: 45 | B40: 46252 | C40: 0.45059028 | D40: MGC | E40: Short | F40: 4444.2 | G40: 4434.5 | H40: 2 | I40: 4447.8 | J40: 4434.5 | K40: =IF(AND(I40<>"",J40<>"",F40<>""), (J40-F40)/(F40-I40), "") | L40: =IF(AND(F40<>"",G40<>"",I40<>""), (G40-F40)/(F40-I40), "") | M40: =IF(N40>0,"Win",IF(N40<0,"Loss","")) | N40: =IF(AND(F40<>"",G40<>"",H40<>"",D40<>""), IF(E40="Long", (G40-F40)*H40*VLOOKUP(D40,Multipliers!A:B,2,FALSE), (F40-G40)*H40*VLOOKUP(D40,Multipliers!A:B,2,FALSE)), "") | O40: =IF(AND(N40<>"",F40<>"",H40<>"",D40<>""), N40/(F40*H40*VLOOKUP(D40,Multipliers!A:B,2,FALSE)), "") | P40: =P39+N40 | Q40: Break and Retest | R40: Imported from Tradovate | S40: MGC
...

Sheet Multipliers
A1: Asset | B1: Multiplier
A2: ES | B2: 50
A3: MES | B3: 5
A4: NQ | B4: 20
A5: MNQ | B5: 2
A6: YM | B6: 5
A7: RTY | B7: 50
A8: GC | B8: 100
A9: MGC | B9: 10
A10: CL | B10: 1000
A11: MCL | B11: 100
A12: QM | B12: 500
A13: MYM | B13: 0.5
A14: M2K | B14: 5

Sheet Tag Options
A1: Rules | B1: Market conditions | C1: Emotion before trade | D1: Setup | E1: Process | F1: Mistakes | G1: Learning | I1: Reference list of suggested tag values — edit freely.
A2: Followed plan | B2: Trending up | C2: Calm | D2: Break and Retest | E2: Pre-market done | F2: Revenge trade | G2: Wait for confluence
A3: Broke a rule | B3: Trending down | C3: Confident | D3: Bounce | E3: Wrote entry reason | F3: Oversized | G3: Size down on news
A4: Within daily loss limit | B4: Ranging | C4: Focused | D4: Rejection | E4: A+ process day | F4: Moved stop | G4: Let winners run
A5: Hit daily loss limit | B5: Choppy | C5: FOMO | D5: 123 Setup | E5: Cooled off between trades | F5: Cut winner early | G5: Honor the stop
A6: Within max size | B6: High volatility | C6: Fear | D6: Pivot | E6: Journaled | F6: Blew stop | G6: Trade only A+
A7: Risked >1R per trade | B7: Low volatility | C7: Greed | D7: A+ setup | E7: No pre-market | F7: No confluence | G7: Reduce overnight trading
A8: Traded planned session | B8: News day | C8: Impatient | D8: Full confluence | E8: Distracted | F8: Early entry | G8: Stick to Pullbacks
A9: Waited for A+ only | B9: Thin / overnight | C9: Frustrated | D9: Breakout | E9: Multitasking | F9: Late entry | G9: Take the 2R
A10: Stopped after 2 losses | B10: Strong trend | C10: Bored | D10: Breakdown | E10: Rushed entry | F10: Overtraded | G10: Be patient
B11: Reversal day | C11: Pressure to recover | D11: Pullback | F11: Chased entry | G11: Smaller size
C12: Tilted | D12: Reversal | F12: Out-of-plan
C13: Anxious | D13: Range fade | F13: No stop
C14: Zen mode | D14: Trend continuation
D15: VWAP bounce
D16: Support / Resistance
D17: Scalping

Sheet Trading Rules
A1: Type | B1: Rule
A2: Hard | B2: Check Economic News.
A3: Hard | B3: Mark Levels before market open. Mark the opening print as a 4/5 Level.
A4: Hard | B4: Create a plan — only long if 1H is uptrend; only short if 1H is downtrend.
A5: Hard | B5: Pick the levels you want to go long/short off based on that analysis. Label the levels AND where the analysis could switch — e.g. an uptrend holds until a level breaks; if the hourly candle closes beneath it, bias can flip down. Mark out both.
A6: Hard | B6: Trade only after 9:45. Don't trade after 12 pm.
A7: Hard | B7: Target 2–2.5 Risk to Reward.
A8: Hard | B8: Aim for 1–3 trades a day with a predefined daily stop loss and an overall assumed profit target.
A9: Other | B9: Re-taking a BR/Bounce at a level that already worked: OK, but with caution. The first Break & Retest/Bounce cleared out most of the immediate sell liquidity, so a second test at the same exact level carries higher break-through risk. Only take it if the 1H trend is still strong — otherwise size down or skip.

Sheet Analysis
A1: Overview
A2: Generated | B2: 2026-08-31 13:16
A3: Date range | B3: 2026-08-11 → 2026-08-31
A4: Trades | B4: 93
A5: Win rate | B5: 54.8%
A6: Total P&L | B6: 2383
A7: Profit factor | B7: 1.3
A8: Expectancy / trade | B8: 25.62
A9: Avg win | B9: 204.53
A10: Avg loss | B10: -191.62
A11: Avg RR targeted | B11: 1.35
A12: Avg RR realized | B12: 0.04
A13: Max drawdown | B13: -1750
A14: Max win streak | B14: 8
A15: Max loss streak | B15: 5
A17: By Setup
A18: Setup | B18: Trades | C18: Win % | D18: Total P&L | E18: Expectancy
A19: Break and Retest | B19: 88 | C19: 53% | D19: 1924 | E19: 21.86
A20: ZTH Indicator | B20: 2 | C20: 100% | D20: 351 | E20: 175.5
A21: Gap up | B21: 1 | C21: 100% | D21: 199 | E21: 199
A22: Rejection | B22: 1 | C22: 100% | D22: 134 | E22: 134
A23: Break and Retest, Rejection | B23: 1 | C23: 0% | D23: -225 | E23: -225
A25: By Instrument
A26: Instrument | B26: Trades | C26: Win % | D26: Total P&L | E26: Expectancy
A27: MGC | B27: 51 | C27: 57% | D27: 2021 | E27: 39.63
A28: MNQ | B28: 42 | C28: 52% | D28: 362 | E28: 8.62
A30: By Direction
A31: Direction | B31: Trades | C31: Win % | D31: Total P&L | E31: Expectancy
A32: Long | B32: 52 | C32: 50% | D32: 2269.5 | E32: 43.64
A33: Short | B33: 41 | C33: 61% | D33: 113.5 | E33: 2.77
A35: By Hour
A36: Hour | B36: Trades | C36: Win % | D36: Total P&L | E36: Expectancy
A37: 00:00 | B37: 4 | C37: 75% | D37: 82 | E37: 20.5
A38: 08:00 | B38: 1 | C38: 0% | D38: -57 | E38: -57
A39: 09:00 | B39: 17 | C39: 71% | D39: 1907.5 | E39: 112.21
A40: 10:00 | B40: 21 | C40: 43% | D40: 206 | E40: 9.81
A41: 11:00 | B41: 10 | C41: 40% | D41: -139 | E41: -13.9
A42: 12:00 | B42: 6 | C42: 83% | D42: -2 | E42: -0.33
A43: 13:00 | B43: 1 | C43: 0% | D43: -255 | E43: -255
A44: 14:00 | B44: 2 | C44: 0% | D44: -402 | E44: -201
...

Sheet AI Suggestions
A1: Claude AI Coaching
A3: Here's the honest read on your August data — the top-line number ($2,383 net, PF 1.3) is masking a much better trader hiding inside a much worse one. Two data cuts below explain almost the entire story.
A5: ## The core finding: your edge is real but you're diluting it 2:1
A7: Your indicator tags happen to partition all 93 trades cleanly into "quality" buckets, and the split is stark:
A9: | Quality signal | Good side | Bad side |
A10: |---|---|---|
A11: | Pullback grade | Good/A+: 34 trades → **+$5,010** | Weak/No setup: 59 trades → **-$2,627** |
A12: | 1H trend alignment | With trend: 55 trades → **+$3,787** | Against/unclear: 38 trades → **-$1,404** |
A13: | At a key level | Yes: 63 trades → **+$4,561** | No: 30 trades → **-$2,178** |
A14: | ADX (trend strength) | ≥20: 59 trades → **+$3,803** | <20 (chop): 34 trades → **-$1,420** |
A15: | Trigger-bar volume | High (≥1.2x): 34 trades → **+$2,514** | Weak: 59 trades → **-$131** |
A17: These aren't 5 different stories — they're the same story told 5 ways: **when you take an A-grade Break and Retest (at a key level, with the 1-hour trend, in a trending ADX regime, on real volume), you have a strong, repeatable edge.** When you take a low-grade version of the same setup — weak pullback, chop, against/unclear trend — you bleed. 59 of your 93 trades (63%) fell into the low-quality bucket this month. If you'd simply passed on those, you'd be sitting closer to **$5,000** net instead of $2,383, with meaningfully less drawdown and screen time. This is the single highest-leverage fix available to you — not a new setup, just stricter filtering of the one you already have.
... A36: 3. **Flag 19:00–23:00 as a reduced-size or no-trade window** unless it's an A+ setup — you have three separate hour-buckets in this window bleeding money, likely from mental fatigue or after-a-loss trading rather than genuinely bad setups at those hours.

Sheet Indicators
A1: Date | B1: Time | C1: Asset | D1: Dir | E1: P&L | F1: 1H Trend | G1: 1H ST | H1: 15m ST | I1: 5m ST | J1: 5m RSI | K1: 5m EMA | L1: 5m MACD | M1: 5m ADX | N1: 5m ATR | O1: VWAP | P1: VWAP Side | Q1: VPOC | R1: RVOL | S1: Est. Delta | T1: Fib % | U1: Fib Zone | V1: Pullback | W1: PB Score | X1: At Level | Y1: Candle | Z1: Trig Vol | AA1: STs Aligned | AB1: With 1H Trend
A2: 2026-08-11 | B2: 19:27 | C2: MGC | D2: Long | E2: 30 | F2: up | G2: down | H2: down | I2: down | J2: 53.8 | K2: bear | L2: - | M2: 17.1 | N2: 3.95 | O2: 4439.45 | P2: below | Q2: 4444.22 | R2: 2.62 | S2: -4577 | T2: 48 | U2: golden | V2: Weak | W2: 1 | X2: Round | Y2: strong bullish close | Z2: 1.78 | AA2: No | AB2: Yes
A3: 2026-08-11 | B3: 19:29 | C3: MGC | D3: Short | E3: 110 | F3: up | G3: down | H3: down | I3: down | J3: 53.8 | K3: bear | L3: - | M3: 17.1 | N3: 3.95 | O3: 4439.45 | P3: below | Q3: 4444.22 | R3: 2.62 | S3: -4577 | T3: 55 | U3: golden | V3: Weak | W3: 1 | X3: Round | Y3: strong bullish close | Z3: 1.78 | AA3: Yes | AB3: No
A4: 2026-08-11 | B4: 19:30 | C4: MGC | D4: Long | E4: -440 | F4: up | G4: down | H4: down | I4: down | J4: 45.1 | K4: bear | L4: - | M4: 17.2 | N4: 4.1 | O4: 4439.37 | P4: below | Q4: 4444.22 | R4: 1.78 | S4: -4716 | T4: 40 | U4: golden | V4: Weak | W4: 1 | X4: Round | Z4: 1.39 | AA4: No | AB4: Yes
A5: 2026-08-11 | B5: 19:34 | C5: MGC | D5: Short | E5: -1310 | F5: up | G5: down | H5: down | I5: down | J5: 45.1 | K5: bear | L5: - | M5: 17.2 | N5: 4.1 | O5: 4439.37 | P5: below | Q5: 4444.22 | R5: 1.78 | S5: -4716 | T5: 40 | U5: golden | V5: Weak | W5: 1 | X5: No | Z5: 1.39 | AA5: Yes | AB5: No
A6: 2026-08-11 | B6: 20:31 | C6: MGC | D6: Long | E6: 370 | F6: up | G6: down | H6: down | I6: up | J6: 67.4 | K6: bull | L6: + | M6: 19 | N6: 3.89 | O6: 4439.2 | P6: above | Q6: 4444.22 | R6: 1.52 | S6: -4008 | T6: 12 | U6: extended (no pullback) | V6: Weak | W6: 1 | X6: Round | Z6: 1.32 | AA6: No | AB6: Yes
A7: 2026-08-11 | B7: 21:16 | C7: MGC | D7: Long | E7: 190 | F7: up | G7: down | H7: up | I7: up | J7: 74.1 | K7: bull | L7: + | M7: 26.8 | N7: 4.03 | O7: 4439.44 | P7: above | Q7: 4444.22 | R7: 1 | S7: -2726 | T7: -18 | U7: extended (no pullback) | V7: Weak | W7: 1 | X7: No | Y7: strong bullish close | Z7: 2.38 | AA7: No | AB7: Yes
A8: 2026-08-11 | B8: 22:40 | C8: MGC | D8: Long | E8: 2160 | F8: up | G8: down | H8: up | I8: up | J8: 75.1 | K8: bull | L8: + | M8: 38 | N8: 4.31 | O8: 4441.14 | P8: above | Q8: 4444.25 | R8: 2.29 | S8: -1849 | T8: 13 | U8: extended (no pullback) | V8: Good | W8: 2 | X8: ORH/Round | Z8: 2.09 | AA8: No | AB8: Yes
A9: 2026-08-11 | B9: 23:00 | C9: MGC | D9: Long | E9: -280 | F9: up | G9: down | H9: up | I9: up | J9: 71.3 | K9: bull | L9: + | M9: 42.7 | N9: 4.49 | O9: 4442.06 | P9: above | Q9: 4440.82 | R9: 1.95 | S9: -1808 | T9: 4 | U9: extended (no pullback) | V9: Weak | W9: 1 | X9: No | Y9: strong bearish close | Z9: 1.18 | AA9: No | AB9: Yes
A10: 2026-08-11 | B10: 23:11 | C10: MGC | D10: Long | E10: -910 | F10: up | G10: down | H10: up | I10: up | J10: 68.9 | K10: bull | L10: + | M10: 44 | N10: 4.68 | O10: 4442.42 | P10: above | Q10: 4444.2 | R10: 2.07 | S10: -1900 | T10: 3 | U10: extended (no pullback) | V10: Weak | W10: 1 | X10: No | Y10: strong bearish close | Z10: 0.77 | AA10: No | AB10: Yes
A11: 2026-08-11 | B11: 23:25 | C11: MGC | D11: Long | E11: -140 | F11: up | G11: down | H11: up | I11: up | J11: 61.4 | K11: bull | L11: - | M11: 40.3 | N11: 4.37 | O11: 4442.73 | P11: above | Q11: 4444.2 | R11: 0.82 | S11: -2055 | T11: 16 | U11: shallow | V11: Weak | W11: 1 | X11: No | Z11: 0.56 | AA11: No | AB11: Yes
A12: 2026-08-11 | B12: 23:36 | C12: MGC | D12: Short | E12: 490 | F12: up | G12: down | H12: up | I12: up | J12: 55.6 | K12: bull | L12: - | M12: 37 | N12: 4.22 | O12: 4442.87 | P12: above | Q12: 4444.2 | R12: 1 | S12: -2358 | T12: -23 | U12: extended (no pullback) | V12: Weak | W12: 1 | X12: Round | Y12: strong bearish close | Z12: 0.45 | AA12: No | AB12: No
A13: 2026-08-12 | B13: 09:12 | C13: MNQ | D13: Long | E13: 47.5 | F13: up | G13: up | H13: up | I13: up | J13: 74.5 | K13: bull | L13: + | M13: 13 | N13: 29.01 | O13: 29698.51 | P13: above | Q13: 29634.79 | R13: 0.81 | S13: -20867 | T13: 5 | U13: extended (no pullback) | V13: No setup | W13: 0 | X13: No | Y13: strong bullish close | Z13: 0.65 | AA13: Yes | AB13: Yes
A14: 2026-08-12 | B14: 09:26 | C14: MGC | D14: Short | E14: 170 | F14: up | G14: up | H14: up | I14: up | J14: 48.6 | K14: bull | L14: - | M14: 14.1 | N14: 9.48 | O14: 4457.92 | P14: above | Q14: 4466.39 | R14: 1.28 | S14: 4436 | T14: 5 | U14: extended (no pullback) | V14: Good | W14: 2 | X14: Round | Y14: strong bullish close | Z14: 0.59 | AA14: No | AB14: No
A15: 2026-08-12 | B15: 09:38 | C15: MNQ | D15: Short | E15: 69.5 | F15: up | G15: up | H15: up | I15: down | J15: 49.1 | K15: bull | L15: - | M15: 15.4 | N15: 38.58 | T15: 36 | U15: shallow | V15: Good | W15: 2 | X15: Round | Z15: 4.74 | AA15: No | AB15: No
A16: 2026-08-12 | B16: 09:51 | C16: MGC | D16: Long | E16: -460 | F16: up | G16: up | H16: up | I16: up | J16: 60 | K16: bull | L16: - | M16: 14.2 | N16: 9.68 | O16: 4478.64 | P16: above | Q16: 4474.18 | R16: 1.15 | S16: 889 | T16: 20 | U16: shallow | V16: Weak | W16: 1 | X16: Round | Y16: strong bullish close | Z16: 0.7 | AA16: Yes | AB16: Yes
A17: 2026-08-12 | B17: 10:55 | C17: MNQ | D17: Long | E17: 93 | F17: up | G17: up | H17: up | I17: down | J17: 45.8 | K17: bear | L17: - | M17: 14.9 | N17: 49.91 | O17: 29904.66 | P17: below | Q17: 29878.13 | R17: 0.78 | S17: -16307 | T17: 55 | U17: golden | V17: Weak | W17: 1 | X17: PDH/ORL/Round | Z17: 0.63 | AA17: No | AB17: Yes
A18: 2026-08-12 | B18: 11:22 | C18: MNQ | D18: Long | E18: 154.5 | F18: up | G18: up | H18: up | I18: down | J18: 43.7 | K18: bear | L18: - | M18: 19.5 | N18: 45.34 | O18: 29900.13 | P18: below | Q18: 29878.13 | R18: 0.62 | S18: -16824 | T18: 59 | U18: golden | V18: Weak | W18: 1 | X18: ORL/Round | Y18: strong bearish close | Z18: 0.49 | AA18: No | AB18: Yes
A19: 2026-08-12 | B19: 11:32 | C19: MNQ | D19: Long | E19: -136.5 | F19: up | G19: up | H19: up | I19: down | J19: 42.1 | K19: bear | L19: - | M19: 21.8 | N19: 45.45 | O19: 29898.1 | P19: below | Q19: 29908.09 | R19: 0.87 | S19: -16568 | T19: 58 | U19: golden | V19: Good | W19: 2 | X19: ORL/Round | Y19: strong bearish close | Z19: 0.82 | AA19: No | AB19: Yes
A20: 2026-08-12 | B20: 11:57 | C20: MNQ | D20: Short | E20: -144 | F20: up | G20: up | H20: up | I20: down | J20: 42.8 | K20: bear | L20: - | M20: 27 | N20: 38.28 | O20: 29893.68 | P20: below | Q20: 29939.9 | R20: 0.64 | S20: -20113 | T20: 11 | U20: extended (no pullback) | V20: No setup | W20: 0 | X20: ORL/Round | Y20: strong bearish close | Z20: 0.47 | AA20: No | AB20: No
A21: 2026-08-12 | B21: 14:12 | C21: MGC | D21: Short | E21: -195 | F21: up | G21: up | H21: up | I21: down | J21: 47 | K21: bear | L21: + | M21: 22.7 | N21: 5.08 | O21: 4478.14 | P21: below | Q21: 4479.5 | R21: 0.73 | S21: -1793 | T21: 22 | U21: shallow | V21: Weak | W21: 1 | X21: No | Y21: strong bullish close | Z21: 0.39 | AA21: No | AB21: No
A22: 2026-08-13 | B22: 08:50 | C22: MGC | D22: Long | E22: -57 | F22: up | G22: down | H22: up | I22: up | J22: 61.3 | K22: bull | L22: + | M22: 26 | N22: 5.68 | O22: 4465.03 | P22: below | Q22: 4479.13 | R22: 0.63 | S22: -1051 | T22: 23 | U22: shallow | V22: Good | W22: 2 | X22: Round | Z22: 0.61 | AA22: No | AB22: Yes
A23: 2026-08-13 | B23: 09:46 | C23: MNQ | D23: Long | E23: 375 | F23: up | G23: up | H23: up | I23: up | J23: 83.7 | K23: bull | L23: + | M23: 32.8 | N23: 39.34 | O23: 29997.1 | P23: above | Q23: 29902.34 | R23: 1.08 | S23: 33183 | T23: 17 | U23: shallow | V23: Weak | W23: 1 | X23: Round | Y23: strong bullish close | Z23: 4.26 | AA23: Yes | AB23: Yes
A24: 2026-08-13 | B24: 11:24 | C24: MGC | D24: Short | E24: 285 | F24: flat | G24: down | H24: down | I24: down | J24: 41.8 | K24: bear | L24: - | M24: 29.6 | N24: 7.33 | O24: 4431.96 | P24: below | Q24: 4430.89 | R24: 1.02 | S24: 1609 | T24: 36 | U24: shallow | V24: Weak | W24: 1 | X24: ORL/Round | Y24: bullish engulfing | Z24: 0.8 | AA24: Yes | AB24: No
A25: 2026-08-13 | B25: 22:50 | C25: MGC | D25: Long | E25: -66 | F25: down | G25: down | H25: down | I25: down | J25: 39.9 | K25: bear | L25: + | M25: 52.4 | N25: 6.07 | O25: 4413.23 | P25: below | Q25: 4431.23 | R25: 0.56 | S25: -5147 | T25: 50 | U25: golden | V25: Weak | W25: 1 | X25: Round | Y25: strong bearish close | Z25: 0.31 | AA25: No | AB25: No
A26: 2026-08-13 | B26: 22:59 | C26: MGC | D26: Short | E26: -195 | F26: down | G26: down | H26: down | I26: down | J26: 39.8 | K26: bear | L26: + | M26: 52.5 | N26: 5.9 | O26: 4413.1 | P26: below | Q26: 4431.23 | R26: 1 | S26: -4987 | T26: 9 | U26: extended (no pullback) | V26: Weak | W26: 1 | X26: Round | Y26: bullish pin/hammer | Z26: 0.48 | AA26: Yes | AB26: Yes
A27: 2026-08-14 | B27: 09:47 | C27: MNQ | D27: Long | E27: 136.5 | F27: up | G27: up | H27: up | I27: down | J27: 46.8 | K27: bear | L27: - | M27: 18 | N27: 27.53 | O27: 30230.3 | P27: above | Q27: 30237.58 | R27: 0.98 | S27: 958 | T27: 43 | U27: golden | V27: Weak | W27: 1 | X27: No | Y27: strong bearish close | Z27: 4.2 | AA27: No | AB27: Yes
A28: 2026-08-14 | B28: 09:57 | C28: MNQ | D28: Long | E28: 27 | F28: up | G28: up | H28: up | I28: down | J28: 44 | K28: bear | L28: - | M28: 17 | N28: 29.86 | O28: 30231.83 | P28: below | Q28: 30229.28 | R28: 0.69 | S28: -683 | T28: 54 | U28: golden | V28: Weak | W28: 1 | X28: No | Z28: 1.7 | AA28: No | AB28: Yes
A29: 2026-08-14 | B29: 11:58 | C29: MNQ | D29: Short | E29: -162 | F29: up | G29: down | H29: down | I29: down | J29: 36.9 | K29: bear | L29: - | M29: 42.4 | N29: 32.23 | O29: 30166.81 | P29: below | Q29: 30239.55 | R29: 1.02 | S29: -24672 | T29: 17 | U29: shallow | V29: No setup | W29: 0 | X29: No | Z29: 0.68 | AA29: Yes | AB29: No
A30: 2026-08-14 | B30: 12:41 | C30: MNQ | D30: Short | E30: 27 | F30: up | G30: down | H30: down | I30: down | J30: 41.4 | K30: bear | L30: + | M30: 35 | N30: 27.31 | O30: 30155.19 | P30: below | Q30: 30239.55 | R30: 0.74 | S30: -26282 | T30: 16 | U30: shallow | V30: No setup | W30: 0 | X30: No | Y30: strong bearish close | Z30: 0.55 | AA30: Yes | AB30: No
A31: 2026-08-14 | B31: 12:46 | C31: MNQ | D31: Long | E31: 42.5 | F31: up | G31: down | H31: down | I31: down | J31: 43.5 | K31: bear | L31: + | M31: 34.7 | N31: 26.45 | O31: 30154.32 | P31: below | Q31: 30239.55 | R31: 0.74 | S31: -24705 | T31: 51 | U31: golden | V31: Good | W31: 2 | X31: No | Y31: strong bullish close | Z31: 0.57 | AA31: No | AB31: Yes
A32: 2026-08-14 | B32: 12:50 | C32: MNQ | D32: Long | E32: 35 | F32: up | G32: down | H32: down | I32: down | J32: 40.7 | K32: bear | L32: + | M32: 34.6 | N32: 25.9 | O32: 30153.37 | P32: below | Q32: 30239.55 | R32: 0.77 | S32: -25488 | T32: 55 | U32: golden | V32: Good | W32: 2 | X32: No | Z32: 0.61 | AA32: No | AB32: Yes
A33: 2026-08-17 | B33: 09:55 | C33: MNQ | D33: Long | E33: -124.5 | F33: up | G33: up | H33: down | I33: down | J33: 50.8 | K33: bear | L33: + | M33: 25.6 | N33: 32.49 | O33: 30212.46 | P33: above | Q33: 30201.93 | R33: 0.67 | S33: -9581 | T33: 15 | U33: shallow | V33: A+ | W33: 3 | X33: Round | Z33: 1.59 | AA33: No | AB33: Yes
A34: 2026-08-17 | B34: 10:09 | C34: MGC | D34: Long | E34: 240 | F34: up | G34: up | H34: up | I34: up | J34: 65.1 | K34: bull | L34: + | M34: 27.7 | N34: 6.23 | O34: 4456.81 | P34: above | Q34: 4457.35 | R34: 0.64 | S34: 604 | T34: 29 | U34: shallow | V34: Weak | W34: 1 | X34: Round | Y34: strong bearish close | Z34: 0.64 | AA34: Yes | AB34: Yes
A35: 2026-08-17 | B35: 11:51 | C35: MNQ | D35: Short | E35: 97.5 | F35: up | G35: up | H35: down | I35: up | J35: 52.5 | K35: bull | L35: - | M35: 17.1 | N35: 29.13 | O35: 30219.99 | P35: above | Q35: 30203.19 | R35: 0.94 | S35: -3153 | T35: 49 | U35: golden | V35: Good | W35: 2 | X35: Round | Y35: bullish engulfing | Z35: 0.86 | AA35: No | AB35: No
A36: 2026-08-18 | B36: 10:00 | C36: MGC | D36: Short | E36: -159 | F36: flat | G36: down | H36: down | I36: up | J36: 59.5 | K36: bull | L36: + | M36: 19.5 | N36: 7.37 | O36: 4452.11 | P36: above | Q36: 4442.54 | R36: 1.51 | S36: 5102 | T36: 53 | U36: golden | V36: Weak | W36: 1 | X36: No | Y36: strong bullish close | Z36: 2.6 | AA36: No | AB36: No
A37: 2026-08-18 | B37: 10:08 | C37: MGC | D37: Long | E37: -180 | F37: flat | G37: down | H37: down | I37: up | J37: 53.1 | K37: bull | L37: + | M37: 18.5 | N37: 7.33 | O37: 4452.43 | P37: above | Q37: 4442.54 | R37: 0.87 | S37: 4347 | T37: 27 | U37: shallow | V37: Weak | W37: 1 | X37: No | Y37: strong bearish close | Z37: 0.75 | AA37: No | AB37: No
A38: 2026-08-18 | B38: 10:16 | C38: MNQ | D38: Short | E38: -80 | F38: down | G38: down | H38: down | I38: down | J38: 38.4 | K38: bear | L38: - | M38: 11.7 | N38: 45.4 | O38: 29665.85 | P38: below | Q38: 29691.77 | R38: 1.23 | S38: -16933 | T38: 21 | U38: shallow | V38: No setup | W38: 0 | X38: ORL/Round | Y38: bullish engulfing | Z38: 1.45 | AA38: Yes | AB38: Yes
A39: 2026-08-18 | B39: 10:21 | C39: MNQ | D39: Short | E39: -295.5 | F39: down | G39: down | H39: down | I39: down | J39: 43.2 | K39: bear | L39: - | M39: 11.2 | N39: 47.03 | O39: 29663.29 | P39: below | Q39: 29691.77 | R39: 1.36 | S39: -13177 | T39: 18 | U39: shallow | V39: No setup | W39: 0 | X39: ORL/Round | Y39: strong bullish close | Z39: 1.34 | AA39: Yes | AB39: Yes
A40: 2026-08-18 | B40: 10:48 | C40: MGC | D40: Short | E40: 194 | F40: flat | G40: down | H40: down | I40: down | J40: 45 | K40: bear | L40: - | M40: 17.3 | N40: 8 | O40: 4449.98 | P40: below | Q40: 4442.54 | R40: 0.97 | S40: 2190 | T40: 35 | U40: shallow | V40: Good | W40: 2 | X40: ONL | Y40: bullish engulfing | Z40: 0.64 | AA40: Yes | AB40: No
...

Sheet Economic News
A1: Date | B1: Time (ET) | C1: Currency | D1: Impact | E1: Event | F1: Actual | G1: Forecast | H1: Previous
A2: 2026-08-13 | B2: 08:30 | C2: USD | D2: High | E2: CPI | F2: 0.2% | G2: 0.2% | H2: 0.0%
A3: 2026-08-14 | B3: 08:30 | C3: USD | D3: High | E3: PPI | F3: 0.2% | G3: 0.3% | H3: 0.4%
A4: 2026-08-15 | B4: 08:30 | C4: USD | D4: High | E4: Retail Sales | F4: -0.3% | G4: 0.2% | H4: -0.2%
A5: 2026-08-20 | B5: 14:00 | C5: USD | D5: High | E5: FOMC Minutes
A6: 2026-08-27 | B6: 08:30 | C6: USD | D6: High | E6: PCE | F6: 0.2% | G6: 0.2% | H6: 0.1%
A7: 2026-08-27 | B7: 08:30 | C7: USD | D7: High | E7: GDP | F7: 1.5% | G7: 1.5% | H7: 2.1%
A8: 2026-08-29 | B8: 10:00 | C8: USD | D8: High | E8: Fed Chair Speaks
A9: 2026-08-29 | B9: 10:00 | C9: USD | D9: High | E9: Payrolls | F9: -79.00K | H9: -862.00K
